Workbook

Sheet DISTRIBUIÇÃO NF4267
A1: NF 4267
A2: xxxxx | J2: pack | K2: pç | L2: pack | M2: pç | N2: pack | O2: pç | P2: pack | Q2: pç | R2: pack | S2: pç | T2: pack | U2: pç | V2: pack | W2: pç | X2: pack | Y2: pç | Z2: pack | AA2: pç | AB2: pack | AC2: pç | AD2: pack | AE2: pç | AF2: pack | AG2: pç | AH2: pack | AI2: pç | AJ2: pack | AK2: pç | AL2: pack | AM2: pç | AN2: pack | AO2: pç | AP2: pack | AQ2: pç | AR2: pack | AS2: pç | AT2: pack | AU2: pç | AV2: pack | AW2: pç | AX2: pack | AY2: pç | AZ2: pack | BA2: pç | BB2: pack | BC2: pç | BD2: pack | BE2: pç | BF2: pack | BG2: pç | BH2: pack | BI2: pç | BJ2: pack | BK2: pç | BL2: pack | BM2: pç | BN2: pack | BO2: pç | BP2: pack | BQ2: pç | BR2: pack | BS2: pç | BT2: pack | BU2: pç | BV2: pack | BW2: pç | BX2: pack | BY2: pç | BZ2: pack | CA2: pç | CB2: pack | CC2: pç | CD2: pack | CE2: pç | CF2: pack | CG2: pç | CH2: pack | CI2: pç | CJ2: pack | CK2: pç | CL2: pack | CM2: pç | CN2: pack | CO2: pç | CP2: pack | CQ2: pç | CR2: pack | CS2: pç | CT2: pack | CU2: pç | CV2: pack | CW2: pç | CX2: pack | CY2: pç | CZ2: pack | DA2: pç | DB2: pack | DC2: pç | DD2: pack | DE2: pç | DF2: pack | DG2: pç | DH2: pack | DI2: pç | DJ2: pack | DK2: pç | DL2: pack | DM2: pç | DN2: pack | DO2: pç | DP2: pack | DQ2: pç | DR2: pack | DS2: pç | DT2: pack | DU2: pç | DV2: pack | DW2: pç | DX2: pack | DY2: pç | DZ2: pack | EA2: pç | EB2: pack | EC2: pç | ED2: pack | EE2: pç | EF2: pack | EG2: pç | EH2: pack | EI2: pç | EJ2: pack | EK2: pç | EL2: pack | EM2: pç | EN2: pack | EO2: pç | EP2: pack | EQ2: pç | ER2: pack | ES2: pç | ET2: pack | EU2: pç | EV2: pack | EW2: pç | EX2: pack | EY2: pç | EZ2: pack | FA2: pç | FB2: pack | FC2: pç | FD2: pack | FE2: pç | FF2: pack | FG2: pç | FH2: pack | FI2: pç | FJ2: pack | FK2: pç | FL2: pack | FM2: pç | FN2: pack | FO2: pç | FP2: pack | FQ2: pç
A3: DESCRIÇÃO | B3: REFERÊNCIA | C3: COR | D3: DESC COR | E3: SKU | F3: TAMANHO | G3: PROPORÇÃO | H3: QT. PACKS | I3: QTDE | J3: 43 | L3: 44 | N3: 24 | P3: BA | R3: 35 | T3: 25 | V3: 48 | X3: I2 | Z3: J5 | AB3: 88 | AD3: 58 | AF3: P1 | AH3: 23 | AJ3: 56 | AL3: I6 | AN3: 28 | AP3: P4 | AR3: BY | AT3: 46 | AV3: 19 | AX3: BX | AZ3: 82 | BB3: 63 | BD3: 33 | BF3: J4 | BH3: J1 | BJ3: 89 | BL3: B0 | BN3: 61 | BP3: O9 | BR3: W3 | BT3: J8 | BV3: J9 | BX3: B3 | BZ3: O2 | CB3: 37 | CD3: O3 | CF3: B2 | CH3: 65 | CJ3: 66 | CL3: AQ | CN3: EX | CP3: 10 | CR3: 50 | CT3: DK | CV3: S7 | CX3: W6 | CZ3: J7 | DB3: 12 | DD3: 85 | DF3: 13 | DH3: EL | DJ3: CF | DL3: B4 | DN3: O7 | DP3: IB | DR3: II | DT3: I9 | DV3: IE | DX3: I0 | DZ3: IJ | EB3: 62 | ED3: Q1 | EF3: N1 | EH3: J3 | EJ3: Q2 | EL3: S5 | EN3: Q3 | EP3: KH | ER3: Q4 | ET3: GX | EV3: 93 | EX3: R1 | EZ3: X6 | FB3: DX | FD3: R3 | FF3: R2 | FH3: GJ | FJ3: KD | FL3: KK | FN3: KR | FP3: KW
A4: CAMISA LISTRAS BRANCAS | B4: 913 | C4: 6D | D4: LISTRA BRANCA | E4: 109130016D1 | F4: 1 | G4: 0 | H4: 320 | I4: =G4*$H$4 -> 0 | J4: 2 | K4: =J4*$G$4 -> 0 | L4: 2 | M4: =L4*$G$4 -> 0 | N4: 2 | O4: =N4*$G$4 -> 0 | P4: 2 | Q4: =P4*$G$4 -> 0 | R4: 2 | S4: =R4*$G$4 -> 0 | T4: 2 | U4: =T4*$G$4 -> 0 | V4: 2 | W4: =V4*$G$4 -> 0 | X4: 2 | Y4: =X4*$G$4 -> 0 | Z4: 2 | AA4: =Z4*$G$4 -> 0 | AB4: 2 | AC4: =AB4*$G$4 -> 0 | AD4: 2 | AE4: =AD4*$G$4 -> 0 | AF4: 2 | AG4: =AF4*$G$4 -> 0 | AH4: 2 | AI4: =AH4*$G$4 -> 0 | AJ4: 2 | AK4: =AJ4*$G$4 -> 0 | AL4: 2 | AM4: =AL4*$G$4 -> 0 | AN4: 2 | AO4: =AN4*$G$4 -> 0 | AP4: 2 | AQ4: =AP4*$G$4 -> 0 | AR4: 2 | AS4: =AR4*$G$4 -> 0 | AT4: 2 | AU4: =AT4*$G$4 -> 0 | AV4: 2 | AW4: =AV4*$G$4 -> 0 | AX4: 2 | AY4: =AX4*$G$4 -> 0 | AZ4: 2 | BA4: =AZ4*$G$4 -> 0 | BB4: 2 | BC4: =BB4*$G$4 -> 0 | BD4: 2 | BE4: =BD4*$G$4 -> 0 | BF4: 2 | BG4: =BF4*$G$4 -> 0 | BH4: 2 | BI4: =BH4*$G$4 -> 0 | BJ4: 2 | BK4: =BJ4*$G$4 -> 0 | BL4: 2 | BM4: =BL4*$G$4 -> 0 | BN4: 2 | BO4: =BN4*$G$4 -> 0 | BP4: 2 | BQ4: =BP4*$G$4 -> 0 | BR4: 2 | BS4: =BR4*$G$4 -> 0 | BT4: 2 | BU4: =BT4*$G$4 -> 0 | BV4: 2 | BW4: =BV4*$G$4 -> 0 | BX4: 2 | BY4: =BX4*$G$4 -> 0 | BZ4: 2 | CA4: =BZ4*$G$4 -> 0 | CB4: 2 | CC4: =CB4*$G$4 -> 0 | CD4: 2 | CE4: =CD4*$G$4 -> 0 | CF4: 2 | CG4: =CF4*$G$4 -> 0 | CH4: 2 | CI4: =CH4*$G$4 -> 0 | CJ4: 2 | CK4: =CJ4*$G$4 -> 0 | CL4: 2 | CM4: =CL4*$G$4 -> 0 | CN4: 2 | CO4: =CN4*$G$4 -> 0 | CP4: 2 | CQ4: =CP4*$G$4 -> 0 | CR4: 2 | CS4: =CR4*$G$4 -> 0 | CT4: 2 | CU4: =CT4*$G$4 -> 0 | CV4: 2 | CW4: =CV4*$G$4 -> 0 | CX4: 2 | CY4: =CX4*$G$4 -> 0 | CZ4: 2 | DA4: =CZ4*$G$4 -> 0 | DB4: 2 | DC4: =DB4*$G$4 -> 0 | DD4: 2 | DE4: =DD4*$G$4 -> 0 | DF4: 2 | DG4: =DF4*$G$4 -> 0 | DH4: 2 | DI4: =DH4*$G$4 -> 0 | DJ4: 2 | DK4: =DJ4*$G$4 -> 0 | DL4: 2 | DM4: =DL4*$G$4 -> 0 | DN4: 2 | DO4: =DN4*$G$4 -> 0 | DP4: 2 | DQ4: =DP4*$G$4 -> 0 | DR4: 2 | DS4: =DR4*$G$4 -> 0 | DT4: 2 | DU4: =DT4*$G$4 -> 0 | DV4: 2 | DW4: =DV4*$G$4 -> 0 | DX4: 2 | DY4: =DX4*$G$4 -> 0 | DZ4: 2 | EA4: =DZ4*$G$4 -> 0 | EB4: 2 | EC4: =EB4*$G$4 -> 0 | ED4: 2 | EE4: =ED4*$G$4 -> 0 | EF4: 2 | EG4: =EF4*$G$4 -> 0 | EH4: 2 | EI4: =EH4*$G$4 -> 0 | EJ4: 2 | EK4: =EJ4*$G$4 -> 0 | EL4: 2 | EM4: =EL4*$G$4 -> 0 | EN4: 2 | EO4: =EN4*$G$4 -> 0 | EP4: 2 | EQ4: =EP4*$G$4 -> 0 | ER4: 2 | ES4: =ER4*$G$4 -> 0 | ET4: 2 | EU4: =ET4*$G$4 -> 0 | EV4: 2 | EW4: =EV4*$G$4 -> 0 | EX4: 2 | EY4: =EX4*$G$4 -> 0 | EZ4: 2 | FA4: =EZ4*$G$4 -> 0 | FB4: 2 | FC4: =FB4*$G$4 -> 0 | FD4: 2 | FE4: =FD4*$G$4 -> 0 | FF4: 2 | FG4: =FF4*$G$4 -> 0 | FH4: 2 | FI4: =FH4*$G$4 -> 0 | FJ4: 2 | FK4: =FJ4*$G$4 -> 0 | FL4: 2 | FM4: =FL4*$G$4 -> 0 | FN4: 2 | FO4: =FN4*$G$4 -> 0 | FP4: 2 | FQ4: =FP4*$G$4 -> 0
A5: CAMISA LISTRAS BRANCAS | B5: 913 | C5: 6D | D5: LISTRA BRANCA | E5: 109130016D2 | F5: 2 | G5: 2 | I5: =G5*$H$4 -> 640 | K5: =J4*$G$5 -> 4 | M5: =L4*$G$5 -> 4 | O5: =N4*$G$5 -> 4 | Q5: =P4*$G$5 -> 4 | S5: =R4*$G$5 -> 4 | U5: =T4*$G$5 -> 4 | W5: =V4*$G$5 -> 4 | Y5: =X4*$G$5 -> 4 | AA5: =Z4*$G$5 -> 4 | AC5: =AB4*$G$5 -> 4 | AE5: =AD4*$G$5 -> 4 | AG5: =AF4*$G$5 -> 4 | AI5: =AH4*$G$5 -> 4 | AK5: =AJ4*$G$5 -> 4 | AM5: =AL4*$G$5 -> 4 | AO5: =AN4*$G$5 -> 4 | AQ5: =AP4*$G$5 -> 4 | AS5: =AR4*$G$5 -> 4 | AU5: =AT4*$G$5 -> 4 | AW5: =AV4*$G$5 -> 4 | AY5: =AX4*$G$5 -> 4 | BA5: =AZ4*$G$5 -> 4 | BC5: =BB4*$G$5 -> 4 | BE5: =BD4*$G$5 -> 4 | BG5: =BF4*$G$5 -> 4 | BI5: =BH4*$G$5 -> 4 | BK5: =BJ4*$G$5 -> 4 | BM5: =BL4*$G$5 -> 4 | BO5: =BN4*$G$5 -> 4 | BQ5: =BP4*$G$5 -> 4 | BS5: =BR4*$G$5 -> 4 | BU5: =BT4*$G$5 -> 4 | BW5: =BV4*$G$5 -> 4 | BY5: =BX4*$G$5 -> 4 | CA5: =BZ4*$G$5 -> 4 | CC5: =CB4*$G$5 -> 4 | CE5: =CD4*$G$5 -> 4 | CG5: =CF4*$G$5 -> 4 | CI5: =CH4*$G$5 -> 4 | CK5: =CJ4*$G$5 -> 4 | CM5: =CL4*$G$5 -> 4 | CO5: =CN4*$G$5 -> 4 | CQ5: =CP4*$G$5 -> 4 | CS5: =CR4*$G$5 -> 4 | CU5: =CT4*$G$5 -> 4 | CW5: =CV4*$G$5 -> 4 | CY5: =CX4*$G$5 -> 4 | DA5: =CZ4*$G$5 -> 4 | DC5: =DB4*$G$5 -> 4 | DE5: =DD4*$G$5 -> 4 | DG5: =DF4*$G$5 -> 4 | DI5: =DH4*$G$5 -> 4 | DK5: =DJ4*$G$5 -> 4 | DM5: =DL4*$G$5 -> 4 | DO5: =DN4*$G$5 -> 4 | DQ5: =DP4*$G$5 -> 4 | DS5: =DR4*$G$5 -> 4 | DU5: =DT4*$G$5 -> 4 | DW5: =DV4*$G$5 -> 4 | DY5: =DX4*$G$5 -> 4 | EA5: =DZ4*$G$5 -> 4 | EC5: =EB4*$G$5 -> 4 | EE5: =ED4*$G$5 -> 4 | EG5: =EF4*$G$5 -> 4 | EI5: =EH4*$G$5 -> 4 | EK5: =EJ4*$G$5 -> 4 | EM5: =EL4*$G$5 -> 4 | EO5: =EN4*$G$5 -> 4 | EQ5: =EP4*$G$5 -> 4 | ES5: =ER4*$G$5 -> 4 | EU5: =ET4*$G$5 -> 4 | EW5: =EV4*$G$5 -> 4 | EY5: =EX4*$G$5 -> 4 | FA5: =EZ4*$G$5 -> 4 | FC5: =FB4*$G$5 -> 4 | FE5: =FD4*$G$5 -> 4 | FG5: =FF4*$G$5 -> 4 | FI5: =FH4*$G$5 -> 4 | FK5: =FJ4*$G$5 -> 4 | FM5: =FL4*$G$5 -> 4 | FO5: =FN4*$G$5 -> 4 | FQ5: =FP4*$G$5 -> 4
A6: CAMISA LISTRAS BRANCAS | B6: 913 | C6: 6D | D6: LISTRA BRANCA | E6: 109130016D3 | F6: 3 | G6: 4 | I6: =G6*$H$4 -> 1280 | K6: =J4*$G$6 -> 8 | M6: =L4*$G$6 -> 8 | O6: =N4*$G$6 -> 8 | Q6: =P4*$G$6 -> 8 | S6: =R4*$G$6 -> 8 | U6: =T4*$G$6 -> 8 | W6: =V4*$G$6 -> 8 | Y6: =X4*$G$6 -> 8 | AA6: =Z4*$G$6 -> 8 | AC6: =AB4*$G$6 -> 8 | AE6: =AD4*$G$6 -> 8 | AG6: =AF4*$G$6 -> 8 | AI6: =AH4*$G$6 -> 8 | AK6: =AJ4*$G$6 -> 8 | AM6: =AL4*$G$6 -> 8 | AO6: =AN4*$G$6 -> 8 | AQ6: =AP4*$G$6 -> 8 | AS6: =AR4*$G$6 -> 8 | AU6: =AT4*$G$6 -> 8 | AW6: =AV4*$G$6 -> 8 | AY6: =AX4*$G$6 -> 8 | BA6: =AZ4*$G$6 -> 8 | BC6: =BB4*$G$6 -> 8 | BE6: =BD4*$G$6 -> 8 | BG6: =BF4*$G$6 -> 8 | BI6: =BH4*$G$6 -> 8 | BK6: =BJ4*$G$6 -> 8 | BM6: =BL4*$G$6 -> 8 | BO6: =BN4*$G$6 -> 8 | BQ6: =BP4*$G$6 -> 8 | BS6: =BR4*$G$6 -> 8 | BU6: =BT4*$G$6 -> 8 | BW6: =BV4*$G$6 -> 8 | BY6: =BX4*$G$6 -> 8 | CA6: =BZ4*$G$6 -> 8 | CC6: =CB4*$G$6 -> 8 | CE6: =CD4*$G$6 -> 8 | CG6: =CF4*$G$6 -> 8 | CI6: =CH4*$G$6 -> 8 | CK6: =CJ4*$G$6 -> 8 | CM6: =CL4*$G$6 -> 8 | CO6: =CN4*$G$6 -> 8 | CQ6: =CP4*$G$6 -> 8 | CS6: =CR4*$G$6 -> 8 | CU6: =CT4*$G$6 -> 8 | CW6: =CV4*$G$6 -> 8 | CY6: =CX4*$G$6 -> 8 | DA6: =CZ4*$G$6 -> 8 | DC6: =DB4*$G$6 -> 8 | DE6: =DD4*$G$6 -> 8 | DG6: =DF4*$G$6 -> 8 | DI6: =DH4*$G$6 -> 8 | DK6: =DJ4*$G$6 -> 8 | DM6: =DL4*$G$6 -> 8 | DO6: =DN4*$G$6 -> 8 | DQ6: =DP4*$G$6 -> 8 | DS6: =DR4*$G$6 -> 8 | DU6: =DT4*$G$6 -> 8 | DW6: =DV4*$G$6 -> 8 | DY6: =DX4*$G$6 -> 8 | EA6: =DZ4*$G$6 -> 8 | EC6: =EB4*$G$6 -> 8 | EE6: =ED4*$G$6 -> 8 | EG6: =EF4*$G$6 -> 8 | EI6: =EH4*$G$6 -> 8 | EK6: =EJ4*$G$6 -> 8 | EM6: =EL4*$G$6 -> 8 | EO6: =EN4*$G$6 -> 8 | EQ6: =EP4*$G$6 -> 8 | ES6: =ER4*$G$6 -> 8 | EU6: =ET4*$G$6 -> 8 | EW6: =EV4*$G$6 -> 8 | EY6: =EX4*$G$6 -> 8 | FA6: =EZ4*$G$6 -> 8 | FC6: =FB4*$G$6 -> 8 | FE6: =FD4*$G$6 -> 8 | FG6: =FF4*$G$6 -> 8 | FI6: =FH4*$G$6 -> 8 | FK6: =FJ4*$G$6 -> 8 | FM6: =FL4*$G$6 -> 8 | FO6: =FN4*$G$6 -> 8 | FQ6: =FP4*$G$6 -> 8
A7: CAMISA LISTRAS BRANCAS | B7: 913 | C7: 6D | D7: LISTRA BRANCA | E7: 109130016D4 | F7: 4 | G7: 2 | I7: =G7*$H$4 -> 640 | K7: =J4*$G$7 -> 4 | M7: =L4*$G$7 -> 4 | O7: =N4*$G$7 -> 4 | Q7: =P4*$G$7 -> 4 | S7: =R4*$G$7 -> 4 | U7: =T4*$G$7 -> 4 | W7: =V4*$G$7 -> 4 | Y7: =X4*$G$7 -> 4 | AA7: =Z4*$G$7 -> 4 | AC7: =AB4*$G$7 -> 4 | AE7: =AD4*$G$7 -> 4 | AG7: =AF4*$G$7 -> 4 | AI7: =AH4*$G$7 -> 4 | AK7: =AJ4*$G$7 -> 4 | AM7: =AL4*$G$7 -> 4 | AO7: =AN4*$G$7 -> 4 | AQ7: =AP4*$G$7 -> 4 | AS7: =AR4*$G$7 -> 4 | AU7: =AT4*$G$7 -> 4 | AW7: =AV4*$G$7 -> 4 | AY7: =AX4*$G$7 -> 4 | BA7: =AZ4*$G$7 -> 4 | BC7: =BB4*$G$7 -> 4 | BE7: =BD4*$G$7 -> 4 | BG7: =BF4*$G$7 -> 4 | BI7: =BH4*$G$7 -> 4 | BK7: =BJ4*$G$7 -> 4 | BM7: =BL4*$G$7 -> 4 | BO7: =BN4*$G$7 -> 4 | BQ7: =BP4*$G$7 -> 4 | BS7: =BR4*$G$7 -> 4 | BU7: =BT4*$G$7 -> 4 | BW7: =BV4*$G$7 -> 4 | BY7: =BX4*$G$7 -> 4 | CA7: =BZ4*$G$7 -> 4 | CC7: =CB4*$G$7 -> 4 | CE7: =CD4*$G$7 -> 4 | CG7: =CF4*$G$7 -> 4 | CI7: =CH4*$G$7 -> 4 | CK7: =CJ4*$G$7 -> 4 | CM7: =CL4*$G$7 -> 4 | CO7: =CN4*$G$7 -> 4 | CQ7: =CP4*$G$7 -> 4 | CS7: =CR4*$G$7 -> 4 | CU7: =CT4*$G$7 -> 4 | CW7: =CV4*$G$7 -> 4 | CY7: =CX4*$G$7 -> 4 | DA7: =CZ4*$G$7 -> 4 | DC7: =DB4*$G$7 -> 4 | DE7: =DD4*$G$7 -> 4 | DG7: =DF4*$G$7 -> 4 | DI7: =DH4*$G$7 -> 4 | DK7: =DJ4*$G$7 -> 4 | DM7: =DL4*$G$7 -> 4 | DO7: =DN4*$G$7 -> 4 | DQ7: =DP4*$G$7 -> 4 | DS7: =DR4*$G$7 -> 4 | DU7: =DT4*$G$7 -> 4 | DW7: =DV4*$G$7 -> 4 | DY7: =DX4*$G$7 -> 4 | EA7: =DZ4*$G$7 -> 4 | EC7: =EB4*$G$7 -> 4 | EE7: =ED4*$G$7 -> 4 | EG7: =EF4*$G$7 -> 4 | EI7: =EH4*$G$7 -> 4 | EK7: =EJ4*$G$7 -> 4 | EM7: =EL4*$G$7 -> 4 | EO7: =EN4*$G$7 -> 4 | EQ7: =EP4*$G$7 -> 4 | ES7: =ER4*$G$7 -> 4 | EU7: =ET4*$G$7 -> 4 | EW7: =EV4*$G$7 -> 4 | EY7: =EX4*$G$7 -> 4 | FA7: =EZ4*$G$7 -> 4 | FC7: =FB4*$G$7 -> 4 | FE7: =FD4*$G$7 -> 4 | FG7: =FF4*$G$7 -> 4 | FI7: =FH4*$G$7 -> 4 | FK7: =FJ4*$G$7 -> 4 | FM7: =FL4*$G$7 -> 4 | FO7: =FN4*$G$7 -> 4 | FQ7: =FP4*$G$7 -> 4
A8: CAMISA LISTRAS BRANCAS | B8: 913 | C8: 6D | D8: LISTRA BRANCA | E8: 109130016D5 | F8: 5 | G8: 2 | I8: =G8*$H$4 -> 640 | K8: =J4*$G$8 -> 4 | M8: =L4*$G$8 -> 4 | O8: =N4*$G$8 -> 4 | Q8: =P4*$G$8 -> 4 | S8: =R4*$G$8 -> 4 | U8: =T4*$G$8 -> 4 | W8: =V4*$G$8 -> 4 | Y8: =X4*$G$8 -> 4 | AA8: =Z4*$G$8 -> 4 | AC8: =AB4*$G$8 -> 4 | AE8: =AD4*$G$8 -> 4 | AG8: =AF4*$G$8 -> 4 | AI8: =AH4*$G$8 -> 4 | AK8: =AJ4*$G$8 -> 4 | AM8: =AL4*$G$8 -> 4 | AO8: =AN4*$G$8 -> 4 | AQ8: =AP4*$G$8 -> 4 | AS8: =AR4*$G$8 -> 4 | AU8: =AT4*$G$8 -> 4 | AW8: =AV4*$G$8 -> 4 | AY8: =AX4*$G$8 -> 4 | BA8: =AZ4*$G$8 -> 4 | BC8: =BB4*$G$8 -> 4 | BE8: =BD4*$G$8 -> 4 | BG8: =BF4*$G$8 -> 4 | BI8: =BH4*$G$8 -> 4 | BK8: =BJ4*$G$8 -> 4 | BM8: =BL4*$G$8 -> 4 | BO8: =BN4*$G$8 -> 4 | BQ8: =BP4*$G$8 -> 4 | BS8: =BR4*$G$8 -> 4 | BU8: =BT4*$G$8 -> 4 | BW8: =BV4*$G$8 -> 4 | BY8: =BX4*$G$8 -> 4 | CA8: =BZ4*$G$8 -> 4 | CC8: =CB4*$G$8 -> 4 | CE8: =CD4*$G$8 -> 4 | CG8: =CF4*$G$8 -> 4 | CI8: =CH4*$G$8 -> 4 | CK8: =CJ4*$G$8 -> 4 | CM8: =CL4*$G$8 -> 4 | CO8: =CN4*$G$8 -> 4 | CQ8: =CP4*$G$8 -> 4 | CS8: =CR4*$G$8 -> 4 | CU8: =CT4*$G$8 -> 4 | CW8: =CV4*$G$8 -> 4 | CY8: =CX4*$G$8 -> 4 | DA8: =CZ4*$G$8 -> 4 | DC8: =DB4*$G$8 -> 4 | DE8: =DD4*$G$8 -> 4 | DG8: =DF4*$G$8 -> 4 | DI8: =DH4*$G$8 -> 4 | DK8: =DJ4*$G$8 -> 4 | DM8: =DL4*$G$8 -> 4 | DO8: =DN4*$G$8 -> 4 | DQ8: =DP4*$G$8 -> 4 | DS8: =DR4*$G$8 -> 4 | DU8: =DT4*$G$8 -> 4 | DW8: =DV4*$G$8 -> 4 | DY8: =DX4*$G$8 -> 4 | EA8: =DZ4*$G$8 -> 4 | EC8: =EB4*$G$8 -> 4 | EE8: =ED4*$G$8 -> 4 | EG8: =EF4*$G$8 -> 4 | EI8: =EH4*$G$8 -> 4 | EK8: =EJ4*$G$8 -> 4 | EM8: =EL4*$G$8 -> 4 | EO8: =EN4*$G$8 -> 4 | EQ8: =EP4*$G$8 -> 4 | ES8: =ER4*$G$8 -> 4 | EU8: =ET4*$G$8 -> 4 | EW8: =EV4*$G$8 -> 4 | EY8: =EX4*$G$8 -> 4 | FA8: =EZ4*$G$8 -> 4 | FC8: =FB4*$G$8 -> 4 | FE8: =FD4*$G$8 -> 4 | FG8: =FF4*$G$8 -> 4 | FI8: =FH4*$G$8 -> 4 | FK8: =FJ4*$G$8 -> 4 | FM8: =FL4*$G$8 -> 4 | FO8: =FN4*$G$8 -> 4 | FQ8: =FP4*$G$8 -> 4
A9: CAMISA LISTRAS BRANCAS | B9: 913 | C9: 6D | D9: LISTRA BRANCA | E9: 109130016D6 | F9: 6 | G9: 0 | I9: =G9*$H$4 -> 0 | K9: =J4*$G$9 -> 0 | M9: =L4*$G$9 -> 0 | O9: =N4*$G$9 -> 0 | Q9: =P4*$G$9 -> 0 | S9: =R4*$G$9 -> 0 | U9: =T4*$G$9 -> 0 | W9: =V4*$G$9 -> 0 | Y9: =X4*$G$9 -> 0 | AA9: =Z4*$G$9 -> 0 | AC9: =AB4*$G$9 -> 0 | AE9: =AD4*$G$9 -> 0 | AG9: =AF4*$G$9 -> 0 | AI9: =AH4*$G$9 -> 0 | AK9: =AJ4*$G$9 -> 0 | AM9: =AL4*$G$9 -> 0 | AO9: =AN4*$G$9 -> 0 | AQ9: =AP4*$G$9 -> 0 | AS9: =AR4*$G$9 -> 0 | AU9: =AT4*$G$9 -> 0 | AW9: =AV4*$G$9 -> 0 | AY9: =AX4*$G$9 -> 0 | BA9: =AZ4*$G$9 -> 0 | BC9: =BB4*$G$9 -> 0 | BE9: =BD4*$G$9 -> 0 | BG9: =BF4*$G$9 -> 0 | BI9: =BH4*$G$9 -> 0 | BK9: =BJ4*$G$9 -> 0 | BM9: =BL4*$G$9 -> 0 | BO9: =BN4*$G$9 -> 0 | BQ9: =BP4*$G$9 -> 0 | BS9: =BR4*$G$9 -> 0 | BU9: =BT4*$G$9 -> 0 | BW9: =BV4*$G$9 -> 0 | BY9: =BX4*$G$9 -> 0 | CA9: =BZ4*$G$9 -> 0 | CC9: =CB4*$G$9 -> 0 | CE9: =CD4*$G$9 -> 0 | CG9: =CF4*$G$9 -> 0 | CI9: =CH4*$G$9 -> 0 | CK9: =CJ4*$G$9 -> 0 | CM9: =CL4*$G$9 -> 0 | CO9: =CN4*$G$9 -> 0 | CQ9: =CP4*$G$9 -> 0 | CS9: =CR4*$G$9 -> 0 | CU9: =CT4*$G$9 -> 0 | CW9: =CV4*$G$9 -> 0 | CY9: =CX4*$G$9 -> 0 | DA9: =CZ4*$G$9 -> 0 | DC9: =DB4*$G$9 -> 0 | DE9: =DD4*$G$9 -> 0 | DG9: =DF4*$G$9 -> 0 | DI9: =DH4*$G$9 -> 0 | DK9: =DJ4*$G$9 -> 0 | DM9: =DL4*$G$9 -> 0 | DO9: =DN4*$G$9 -> 0 | DQ9: =DP4*$G$9 -> 0 | DS9: =DR4*$G$9 -> 0 | DU9: =DT4*$G$9 -> 0 | DW9: =DV4*$G$9 -> 0 | DY9: =DX4*$G$9 -> 0 | EA9: =DZ4*$G$9 -> 0 | EC9: =EB4*$G$9 -> 0 | EE9: =ED4*$G$9 -> 0 | EG9: =EF4*$G$9 -> 0 | EI9: =EH4*$G$9 -> 0 | EK9: =EJ4*$G$9 -> 0 | EM9: =EL4*$G$9 -> 0 | EO9: =EN4*$G$9 -> 0 | EQ9: =EP4*$G$9 -> 0 | ES9: =ER4*$G$9 -> 0 | EU9: =ET4*$G$9 -> 0 | EW9: =EV4*$G$9 -> 0 | EY9: =EX4*$G$9 -> 0 | FA9: =EZ4*$G$9 -> 0 | FC9: =FB4*$G$9 -> 0 | FE9: =FD4*$G$9 -> 0 | FG9: =FF4*$G$9 -> 0 | FI9: =FH4*$G$9 -> 0 | FK9: =FJ4*$G$9 -> 0 | FM9: =FL4*$G$9 -> 0 | FO9: =FN4*$G$9 -> 0 | FQ9: =FP4*$G$9 -> 0
A10: CAMISA LISTRAS BRANCAS | B10: 913 | C10: 5B | D10: LISTRA BRANCA | E10: 109130015B1 | F10: 1 | G10: 0 | H10: 117 | I10: =G10*$H10 -> 0 | J10: 3 | K10: =J10*G10 -> 0 | L10: 3 | M10: =L10*$G$10 -> 0 | N10: 3 | O10: =N10*$G$10 -> 0 | P10: 3 | Q10: =P10*$G$10 -> 0 | R10: 3 | S10: =R10*$G$10 -> 0 | T10: 3 | U10: =T10*$G$10 -> 0 | V10: 3 | W10: =V10*$G$10 -> 0 | X10: 3 | Y10: =X10*$G$10 -> 0 | Z10: 3 | AA10: =Z10*$G$10 -> 0 | AB10: 3 | AC10: =AB10*$G$10 -> 0 | AD10: 3 | AE10: =AD10*$G$10 -> 0 | AF10: 3 | AG10: =AF10*$G$10 -> 0 | AH10: 3 | AI10: =AH10*$G$10 -> 0 | AJ10: 3 | AK10: =AJ10*$G$10 -> 0 | AL10: 3 | AM10: =AL10*$G$10 -> 0 | AN10: 2 | AO10: =AN10*$G$10 -> 0 | AP10: 1 | AQ10: =AP10*$G$10 -> 0 | AR10: 1 | AS10: =AR10*$G$10 -> 0 | AT10: 1 | AU10: =AT10*$G$10 -> 0 | AV10: 1 | AW10: =AV10*$G$10 -> 0 | AX10: 1 | AY10: =AX10*$G$10 -> 0 | AZ10: 1 | BA10: =AZ10*$G$10 -> 0 | BB10: 1 | BC10: =BB10*$G$10 -> 0 | BD10: 1 | BE10: =BD10*$G$10 -> 0 | BF10: 1 | BG10: =BF10*$G$10 -> 0 | BH10: 1 | BI10: =BH10*$G$10 -> 0 | BJ10: 1 | BK10: =BJ10*$G$10 -> 0 | BL10: 1 | BM10: =BL10*$G$10 -> 0 | BN10: 1 | BO10: =BN10*$G$10 -> 0 | BP10: 1 | BQ10: =BP10*$G$10 -> 0 | BR10: 1 | BS10: =BR10*$G$10 -> 0 | BT10: 1 | BU10: =BT10*$G$10 -> 0 | BV10: 1 | BW10: =BV10*$G$10 -> 0 | BX10: 1 | BY10: =BX10*$G$10 -> 0 | BZ10: 1 | CA10: =BZ10*$G$10 -> 0 | CB10: 1 | CC10: =CB10*$G$10 -> 0 | CD10: 1 | CE10: =CD10*$G$10 -> 0 | CF10: 1 | CG10: =CF10*$G$10 -> 0 | CH10: 1 | CI10: =CH10*$G$10 -> 0 | CJ10: 1 | CK10: =CJ10*$G$10 -> 0 | CL10: 1 | CM10: =CL10*$G$10 -> 0 | CN10: 1 | CO10: =CN10*$G$10 -> 0 | CP10: 1 | CQ10: =CP10*$G$10 -> 0 | CR10: 1 | CS10: =CR10*$G$10 -> 0 | CT10: 1 | CU10: =CT10*$G$10 -> 0 | CV10: 1 | CW10: =CV10*$G$10 -> 0 | CX10: 1 | CY10: =CX10*$G$10 -> 0 | CZ10: 1 | DA10: =CZ10*$G$10 -> 0 | DB10: 1 | DC10: =DB10*$G$10 -> 0 | DD10: 1 | DE10: =DD10*$G$10 -> 0 | DF10: 1 | DG10: =DF10*$G$10 -> 0 | DH10: 1 | DI10: =DH10*$G$10 -> 0 | DJ10: 1 | DK10: =DJ10*$G$10 -> 0 | DL10: 1 | DM10: =DL10*$G$10 -> 0 | DN10: 1 | DO10: =DN10*$G$10 -> 0 | DP10: 1 | DQ10: =DP10*$G$10 -> 0 | DR10: 1 | DS10: =DR10*$G$10 -> 0 | DT10: 1 | DU10: =DT10*$G$10 -> 0 | DV10: 1 | DW10: =DV10*$G$10 -> 0 | DX10: 1 | DY10: =DX10*$G$10 -> 0 | DZ10: 1 | EA10: =DZ10*$G$10 -> 0 | EB10: 1 | EC10: =EB10*$G$10 -> 0 | ED10: 1 | EE10: =ED10*$G$10 -> 0 | EF10: 1 | EG10: =EF10*$G$10 -> 0 | EH10: 1 | EI10: =EH10*$G$10 -> 0 | EJ10: 1 | EK10: =EJ10*$G$10 -> 0 | EL10: 1 | EM10: =EL10*$G$10 -> 0 | EN10: 1 | EO10: =EN10*$G$10 -> 0 | EP10: 1 | EQ10: =EP10*$G$10 -> 0 | ER10: 1 | ES10: =ER10*$G$10 -> 0 | ET10: 1 | EU10: =ET10*$G$10 -> 0 | EV10: 1 | EW10: =EV10*$G$10 -> 0 | EX10: 1 | EY10: =EX10*$G$10 -> 0 | EZ10: 1 | FA10: =EZ10*$G$10 -> 0 | FB10: 1 | FC10: =FB10*$G$10 -> 0 | FD10: 1 | FE10: =FD10*$G$10 -> 0 | FF10: 1 | FG10: =FF10*$G$10 -> 0 | FH10: 1 | FI10: =FH10*$G$10 -> 0 | FJ10: 1 | FK10: =FJ10*$G$10 -> 0 | FL10: 1 | FM10: =FL10*$G$10 -> 0 | FN10: 1 | FO10: =FN10*$G$10 -> 0 | FP10: 2 | FQ10: =FP10*$G$10 -> 0
A11: CAMISA LISTRAS BRANCAS | B11: 913 | C11: 5B | D11: LISTRA BRANCA | E11: 109130015B2 | F11: 2 | G11: 2 | I11: =G11*$H$10 -> 234 | K11: =J10*G11 -> 6 | M11: =L10*$G$11 -> 6 | O11: =N10*$G$11 -> 6 | Q11: =P10*$G$11 -> 6 | S11: =R10*$G$11 -> 6 | U11: =T10*$G$11 -> 6 | W11: =V10*$G$11 -> 6 | Y11: =X10*$G$11 -> 6 | AA11: =Z10*$G$11 -> 6 | AC11: =AB10*$G$11 -> 6 | AE11: =AD10*$G$11 -> 6 | AG11: =AF10*$G$11 -> 6 | AI11: =AH10*$G$11 -> 6 | AK11: =AJ10*$G$11 -> 6 | AM11: =AL10*$G$11 -> 6 | AO11: =AN10*$G$11 -> 4 | AQ11: =AP10*$G$11 -> 2 | AS11: =AR10*$G$11 -> 2 | AU11: =AT10*$G$11 -> 2 | AW11: =AV10*$G$11 -> 2 | AY11: =AX10*$G$11 -> 2 | BA11: =AZ10*$G$11 -> 2 | BC11: =BB10*$G$11 -> 2 | BE11: =BD10*$G$11 -> 2 | BG11: =BF10*$G$11 -> 2 | BI11: =BH10*$G$11 -> 2 | BK11: =BJ10*$G$11 -> 2 | BM11: =BL10*$G$11 -> 2 | BO11: =BN10*$G$11 -> 2 | BQ11: =BP10*$G$11 -> 2 | BS11: =BR10*$G$11 -> 2 | BU11: =BT10*$G$11 -> 2 | BW11: =BV10*$G$11 -> 2 | BY11: =BX10*$G$11 -> 2 | CA11: =BZ10*$G$11 -> 2 | CC11: =CB10*$G$11 -> 2 | CE11: =CD10*$G$11 -> 2 | CG11: =CF10*$G$11 -> 2 | CI11: =CH10*$G$11 -> 2 | CK11: =CJ10*$G$11 -> 2 | CM11: =CL10*$G$11 -> 2 | CO11: =CN10*$G$11 -> 2 | CQ11: =CP10*$G$11 -> 2 | CS11: =CR10*$G$11 -> 2 | CU11: =CT10*$G$11 -> 2 | CW11: =CV10*$G$11 -> 2 | CY11: =CX10*$G$11 -> 2 | DA11: =CZ10*$G$11 -> 2 | DC11: =DB10*$G$11 -> 2 | DE11: =DD10*$G$11 -> 2 | DG11: =DF10*$G$11 -> 2 | DI11: =DH10*$G$11 -> 2 | DK11: =DJ10*$G$11 -> 2 | DM11: =DL10*$G$11 -> 2 | DO11: =DN10*$G$11 -> 2 | DQ11: =DP10*$G$11 -> 2 | DS11: =DR10*$G$11 -> 2 | DU11: =DT10*$G$11 -> 2 | DW11: =DV10*$G$11 -> 2 | DY11: =DX10*$G$11 -> 2 | EA11: =DZ10*$G$11 -> 2 | EC11: =EB10*$G$11 -> 2 | EE11: =ED10*$G$11 -> 2 | EG11: =EF10*$G$11 -> 2 | EI11: =EH10*$G$11 -> 2 | EK11: =EJ10*$G$11 -> 2 | EM11: =EL10*$G$11 -> 2 | EO11: =EN10*$G$11 -> 2 | EQ11: =EP10*$G$11 -> 2 | ES11: =ER10*$G$11 -> 2 | EU11: =ET10*$G$11 -> 2 | EW11: =EV10*$G$11 -> 2 | EY11: =EX10*$G$11 -> 2 | FA11: =EZ10*$G$11 -> 2 | FC11: =FB10*$G$11 -> 2 | FE11: =FD10*$G$11 -> 2 | FG11: =FF10*$G$11 -> 2 | FI11: =FH10*$G$11 -> 2 | FK11: =FJ10*$G$11 -> 2 | FM11: =FL10*$G$11 -> 2 | FO11: =FN10*$G$11 -> 2 | FQ11: =FP10*$G$11 -> 4
A12: CAMISA LISTRAS BRANCAS | B12: 913 | C12: 5B | D12: LISTRA BRANCA | E12: 109130015B3 | F12: 3 | G12: 4 | I12: =G12*$H$10 -> 468 | K12: =J10*G12 -> 12 | M12: =L10*$G$12 -> 12 | O12: =N10*$G$12 -> 12 | Q12: =P10*$G$12 -> 12 | S12: =R10*$G$12 -> 12 | U12: =T10*$G$12 -> 12 | W12: =V10*$G$12 -> 12 | Y12: =X10*$G$12 -> 12 | AA12: =Z10*$G$12 -> 12 | AC12: =AB10*$G$12 -> 12 | AE12: =AD10*$G$12 -> 12 | AG12: =AF10*$G$12 -> 12 | AI12: =AH10*$G$12 -> 12 | AK12: =AJ10*$G$12 -> 12 | AM12: =AL10*$G$12 -> 12 | AO12: =AN10*$G$12 -> 8 | AQ12: =AP10*$G$12 -> 4 | AS12: =AR10*$G$12 -> 4 | AU12: =AT10*$G$12 -> 4 | AW12: =AV10*$G$12 -> 4 | AY12: =AX10*$G$12 -> 4 | BA12: =AZ10*$G$12 -> 4 | BC12: =BB10*$G$12 -> 4 | BE12: =BD10*$G$12 -> 4 | BG12: =BF10*$G$12 -> 4 | BI12: =BH10*$G$12 -> 4 | BK12: =BJ10*$G$12 -> 4 | BM12: =BL10*$G$12 -> 4 | BO12: =BN10*$G$12 -> 4 | BQ12: =BP10*$G$12 -> 4 | BS12: =BR10*$G$12 -> 4 | BU12: =BT10*$G$12 -> 4 | BW12: =BV10*$G$12 -> 4 | BY12: =BX10*$G$12 -> 4 | CA12: =BZ10*$G$12 -> 4 | CC12: =CB10*$G$12 -> 4 | CE12: =CD10*$G$12 -> 4 | CG12: =CF10*$G$12 -> 4 | CI12: =CH10*$G$12 -> 4 | CK12: =CJ10*$G$12 -> 4 | CM12: =CL10*$G$12 -> 4 | CO12: =CN10*$G$12 -> 4 | CQ12: =CP10*$G$12 -> 4 | CS12: =CR10*$G$12 -> 4 | CU12: =CT10*$G$12 -> 4 | CW12: =CV10*$G$12 -> 4 | CY12: =CX10*$G$12 -> 4 | DA12: =CZ10*$G$12 -> 4 | DC12: =DB10*$G$12 -> 4 | DE12: =DD10*$G$12 -> 4 | DG12: =DF10*$G$12 -> 4 | DI12: =DH10*$G$12 -> 4 | DK12: =DJ10*$G$12 -> 4 | DM12: =DL10*$G$12 -> 4 | DO12: =DN10*$G$12 -> 4 | DQ12: =DP10*$G$12 -> 4 | DS12: =DR10*$G$12 -> 4 | DU12: =DT10*$G$12 -> 4 | DW12: =DV10*$G$12 -> 4 | DY12: =DX10*$G$12 -> 4 | EA12: =DZ10*$G$12 -> 4 | EC12: =EB10*$G$12 -> 4 | EE12: =ED10*$G$12 -> 4 | EG12: =EF10*$G$12 -> 4 | EI12: =EH10*$G$12 -> 4 | EK12: =EJ10*$G$12 -> 4 | EM12: =EL10*$G$12 -> 4 | EO12: =EN10*$G$12 -> 4 | EQ12: =EP10*$G$12 -> 4 | ES12: =ER10*$G$12 -> 4 | EU12: =ET10*$G$12 -> 4 | EW12: =EV10*$G$12 -> 4 | EY12: =EX10*$G$12 -> 4 | FA12: =EZ10*$G$12 -> 4 | FC12: =FB10*$G$12 -> 4 | FE12: =FD10*$G$12 -> 4 | FG12: =FF10*$G$12 -> 4 | FI12: =FH10*$G$12 -> 4 | FK12: =FJ10*$G$12 -> 4 | FM12: =FL10*$G$12 -> 4 | FO12: =FN10*$G$12 -> 4 | FQ12: =FP10*$G$12 -> 8
A13: CAMISA LISTRAS BRANCAS | B13: 913 | C13: 5B | D13: LISTRA BRANCA | E13: 109130015B4 | F13: 4 | G13: 2 | I13: =G13*$H$10 -> 234 | K13: =J10*G13 -> 6 | M13: =L10*$G$13 -> 6 | O13: =N10*$G$13 -> 6 | Q13: =P10*$G$13 -> 6 | S13: =R10*$G$13 -> 6 | U13: =T10*$G$13 -> 6 | W13: =V10*$G$13 -> 6 | Y13: =X10*$G$13 -> 6 | AA13: =Z10*$G$13 -> 6 | AC13: =AB10*$G$13 -> 6 | AE13: =AD10*$G$13 -> 6 | AG13: =AF10*$G$13 -> 6 | AI13: =AH10*$G$13 -> 6 | AK13: =AJ10*$G$13 -> 6 | AM13: =AL10*$G$13 -> 6 | AO13: =AN10*$G$13 -> 4 | AQ13: =AP10*$G$13 -> 2 | AS13: =AR10*$G$13 -> 2 | AU13: =AT10*$G$13 -> 2 | AW13: =AV10*$G$13 -> 2 | AY13: =AX10*$G$13 -> 2 | BA13: =AZ10*$G$13 -> 2 | BC13: =BB10*$G$13 -> 2 | BE13: =BD10*$G$13 -> 2 | BG13: =BF10*$G$13 -> 2 | BI13: =BH10*$G$13 -> 2 | BK13: =BJ10*$G$13 -> 2 | BM13: =BL10*$G$13 -> 2 | BO13: =BN10*$G$13 -> 2 | BQ13: =BP10*$G$13 -> 2 | BS13: =BR10*$G$13 -> 2 | BU13: =BT10*$G$13 -> 2 | BW13: =BV10*$G$13 -> 2 | BY13: =BX10*$G$13 -> 2 | CA13: =BZ10*$G$13 -> 2 | CC13: =CB10*$G$13 -> 2 | CE13: =CD10*$G$13 -> 2 | CG13: =CF10*$G$13 -> 2 | CI13: =CH10*$G$13 -> 2 | CK13: =CJ10*$G$13 -> 2 | CM13: =CL10*$G$13 -> 2 | CO13: =CN10*$G$13 -> 2 | CQ13: =CP10*$G$13 -> 2 | CS13: =CR10*$G$13 -> 2 | CU13: =CT10*$G$13 -> 2 | CW13: =CV10*$G$13 -> 2 | CY13: =CX10*$G$13 -> 2 | DA13: =CZ10*$G$13 -> 2 | DC13: =DB10*$G$13 -> 2 | DE13: =DD10*$G$13 -> 2 | DG13: =DF10*$G$13 -> 2 | DI13: =DH10*$G$13 -> 2 | DK13: =DJ10*$G$13 -> 2 | DM13: =DL10*$G$13 -> 2 | DO13: =DN10*$G$13 -> 2 | DQ13: =DP10*$G$13 -> 2 | DS13: =DR10*$G$13 -> 2 | DU13: =DT10*$G$13 -> 2 | DW13: =DV10*$G$13 -> 2 | DY13: =DX10*$G$13 -> 2 | EA13: =DZ10*$G$13 -> 2 | EC13: =EB10*$G$13 -> 2 | EE13: =ED10*$G$13 -> 2 | EG13: =EF10*$G$13 -> 2 | EI13: =EH10*$G$13 -> 2 | EK13: =EJ10*$G$13 -> 2 | EM13: =EL10*$G$13 -> 2 | EO13: =EN10*$G$13 -> 2 | EQ13: =EP10*$G$13 -> 2 | ES13: =ER10*$G$13 -> 2 | EU13: =ET10*$G$13 -> 2 | EW13: =EV10*$G$13 -> 2 | EY13: =EX10*$G$13 -> 2 | FA13: =EZ10*$G$13 -> 2 | FC13: =FB10*$G$13 -> 2 | FE13: =FD10*$G$13 -> 2 | FG13: =FF10*$G$13 -> 2 | FI13: =FH10*$G$13 -> 2 | FK13: =FJ10*$G$13 -> 2 | FM13: =FL10*$G$13 -> 2 | FO13: =FN10*$G$13 -> 2 | FQ13: =FP10*$G$13 -> 4
A14: CAMISA LISTRAS BRANCAS | B14: 913 | C14: 5B | D14: LISTRA BRANCA | E14: 109130015B5 | F14: 5 | G14: 2 | I14: =G14*$H$10 -> 234 | K14: =J10*G14 -> 6 | M14: =L10*$G$14 -> 6 | O14: =N10*$G$14 -> 6 | Q14: =P10*$G$14 -> 6 | S14: =R10*$G$14 -> 6 | U14: =T10*$G$14 -> 6 | W14: =V10*$G$14 -> 6 | Y14: =X10*$G$14 -> 6 | AA14: =Z10*$G$14 -> 6 | AC14: =AB10*$G$14 -> 6 | AE14: =AD10*$G$14 -> 6 | AG14: =AF10*$G$14 -> 6 | AI14: =AH10*$G$14 -> 6 | AK14: =AJ10*$G$14 -> 6 | AM14: =AL10*$G$14 -> 6 | AO14: =AN10*$G$14 -> 4 | AQ14: =AP10*$G$14 -> 2 | AS14: =AR10*$G$14 -> 2 | AU14: =AT10*$G$14 -> 2 | AW14: =AV10*$G$14 -> 2 | AY14: =AX10*$G$14 -> 2 | BA14: =AZ10*$G$14 -> 2 | BC14: =BB10*$G$14 -> 2 | BE14: =BD10*$G$14 -> 2 | BG14: =BF10*$G$14 -> 2 | BI14: =BH10*$G$14 -> 2 | BK14: =BJ10*$G$14 -> 2 | BM14: =BL10*$G$14 -> 2 | BO14: =BN10*$G$14 -> 2 | BQ14: =BP10*$G$14 -> 2 | BS14: =BR10*$G$14 -> 2 | BU14: =BT10*$G$14 -> 2 | BW14: =BV10*$G$14 -> 2 | BY14: =BX10*$G$14 -> 2 | CA14: =BZ10*$G$14 -> 2 | CC14: =CB10*$G$14 -> 2 | CE14: =CD10*$G$14 -> 2 | CG14: =CF10*$G$14 -> 2 | CI14: =CH10*$G$14 -> 2 | CK14: =CJ10*$G$14 -> 2 | CM14: =CL10*$G$14 -> 2 | CO14: =CN10*$G$14 -> 2 | CQ14: =CP10*$G$14 -> 2 | CS14: =CR10*$G$14 -> 2 | CU14: =CT10*$G$14 -> 2 | CW14: =CV10*$G$14 -> 2 | CY14: =CX10*$G$14 -> 2 | DA14: =CZ10*$G$14 -> 2 | DC14: =DB10*$G$14 -> 2 | DE14: =DD10*$G$14 -> 2 | DG14: =DF10*$G$14 -> 2 | DI14: =DH10*$G$14 -> 2 | DK14: =DJ10*$G$14 -> 2 | DM14: =DL10*$G$14 -> 2 | DO14: =DN10*$G$14 -> 2 | DQ14: =DP10*$G$14 -> 2 | DS14: =DR10*$G$14 -> 2 | DU14: =DT10*$G$14 -> 2 | DW14: =DV10*$G$14 -> 2 | DY14: =DX10*$G$14 -> 2 | EA14: =DZ10*$G$14 -> 2 | EC14: =EB10*$G$14 -> 2 | EE14: =ED10*$G$14 -> 2 | EG14: =EF10*$G$14 -> 2 | EI14: =EH10*$G$14 -> 2 | EK14: =EJ10*$G$14 -> 2 | EM14: =EL10*$G$14 -> 2 | EO14: =EN10*$G$14 -> 2 | EQ14: =EP10*$G$14 -> 2 | ES14: =ER10*$G$14 -> 2 | EU14: =ET10*$G$14 -> 2 | EW14: =EV10*$G$14 -> 2 | EY14: =EX10*$G$14 -> 2 | FA14: =EZ10*$G$14 -> 2 | FC14: =FB10*$G$14 -> 2 | FE14: =FD10*$G$14 -> 2 | FG14: =FF10*$G$14 -> 2 | FI14: =FH10*$G$14 -> 2 | FK14: =FJ10*$G$14 -> 2 | FM14: =FL10*$G$14 -> 2 | FO14: =FN10*$G$14 -> 2 | FQ14: =FP10*$G$14 -> 4
A15: CAMISA LISTRAS BRANCAS | B15: 913 | C15: 5B | D15: LISTRA BRANCA | E15: 109130015B6 | F15: 6 | G15: 0 | I15: =G15*$H$10 -> 0 | K15: =J10*G15 -> 0 | M15: =L10*$G$15 -> 0 | O15: =N10*$G$15 -> 0 | Q15: =P10*$G$15 -> 0 | S15: =R10*$G$15 -> 0 | U15: =T10*$G$15 -> 0 | W15: =V10*$G$15 -> 0 | Y15: =X10*$G$15 -> 0 | AA15: =Z10*$G$15 -> 0 | AC15: =AB10*$G$15 -> 0 | AE15: =AD10*$G$15 -> 0 | AG15: =AF10*$G$15 -> 0 | AI15: =AH10*$G$15 -> 0 | AK15: =AJ10*$G$15 -> 0 | AM15: =AL10*$G$15 -> 0 | AO15: =AN10*$G$15 -> 0 | AQ15: =AP10*$G$15 -> 0 | AS15: =AR10*$G$15 -> 0 | AU15: =AT10*$G$15 -> 0 | AW15: =AV10*$G$15 -> 0 | AY15: =AX10*$G$15 -> 0 | BA15: =AZ10*$G$15 -> 0 | BC15: =BB10*$G$15 -> 0 | BE15: =BD10*$G$15 -> 0 | BG15: =BF10*$G$15 -> 0 | BI15: =BH10*$G$15 -> 0 | BK15: =BJ10*$G$15 -> 0 | BM15: =BL10*$G$15 -> 0 | BO15: =BN10*$G$15 -> 0 | BQ15: =BP10*$G$15 -> 0 | BS15: =BR10*$G$15 -> 0 | BU15: =BT10*$G$15 -> 0 | BW15: =BV10*$G$15 -> 0 | BY15: =BX10*$G$15 -> 0 | CA15: =BZ10*$G$15 -> 0 | CC15: =CB10*$G$15 -> 0 | CE15: =CD10*$G$15 -> 0 | CG15: =CF10*$G$15 -> 0 | CI15: =CH10*$G$15 -> 0 | CK15: =CJ10*$G$15 -> 0 | CM15: =CL10*$G$15 -> 0 | CO15: =CN10*$G$15 -> 0 | CQ15: =CP10*$G$15 -> 0 | CS15: =CR10*$G$15 -> 0 | CU15: =CT10*$G$15 -> 0 | CW15: =CV10*$G$15 -> 0 | CY15: =CX10*$G$15 -> 0 | DA15: =CZ10*$G$15 -> 0 | DC15: =DB10*$G$15 -> 0 | DE15: =DD10*$G$15 -> 0 | DG15: =DF10*$G$15 -> 0 | DI15: =DH10*$G$15 -> 0 | DK15: =DJ10*$G$15 -> 0 | DM15: =DL10*$G$15 -> 0 | DO15: =DN10*$G$15 -> 0 | DQ15: =DP10*$G$15 -> 0 | DS15: =DR10*$G$15 -> 0 | DU15: =DT10*$G$15 -> 0 | DW15: =DV10*$G$15 -> 0 | DY15: =DX10*$G$15 -> 0 | EA15: =DZ10*$G$15 -> 0 | EC15: =EB10*$G$15 -> 0 | EE15: =ED10*$G$15 -> 0 | EG15: =EF10*$G$15 -> 0 | EI15: =EH10*$G$15 -> 0 | EK15: =EJ10*$G$15 -> 0 | EM15: =EL10*$G$15 -> 0 | EO15: =EN10*$G$15 -> 0 | EQ15: =EP10*$G$15 -> 0 | ES15: =ER10*$G$15 -> 0 | EU15: =ET10*$G$15 -> 0 | EW15: =EV10*$G$15 -> 0 | EY15: =EX10*$G$15 -> 0 | FA15: =EZ10*$G$15 -> 0 | FC15: =FB10*$G$15 -> 0 | FE15: =FD10*$G$15 -> 0 | FG15: =FF10*$G$15 -> 0 | FI15: =FH10*$G$15 -> 0 | FK15: =FJ10*$G$15 -> 0 | FM15: =FL10*$G$15 -> 0 | FO15: =FN10*$G$15 -> 0 | FQ15: =FP10*$G$15 -> 0
A16: CAMISA LISTRAS BRANCAS | B16: 913 | C16: 9E | D16: LISTRA BRANCA | E16: 109130019E1 | F16: 1 | G16: 0 | H16: 136 | I16: =H16*G16 -> 0 | J16: 3 | K16: =J16*$G$16 -> 0 | L16: 3 | M16: =L16*$G$16 -> 0 | N16: 3 | O16: =N16*$G$16 -> 0 | P16: 3 | Q16: =P16*$G$16 -> 0 | R16: 3 | S16: =R16*$G$16 -> 0 | T16: 3 | U16: =T16*$G$16 -> 0 | V16: 3 | W16: =V16*$G$16 -> 0 | X16: 3 | Y16: =X16*$G$16 -> 0 | Z16: 3 | AA16: =Z16*$G$16 -> 0 | AB16: 3 | AC16: =AB16*$G$16 -> 0 | AD16: 3 | AE16: =AD16*$G$16 -> 0 | AF16: 3 | AG16: =AF16*$G$16 -> 0 | AH16: 2 | AI16: =AH16*$G$16 -> 0 | AJ16: 2 | AK16: =AJ16*$G$16 -> 0 | AL16: 2 | AM16: =AL16*$G$16 -> 0 | AN16: 2 | AO16: =AN16*$G$16 -> 0 | AP16: 2 | AQ16: =AP16*$G$16 -> 0 | AR16: 2 | AS16: =AR16*$G$16 -> 0 | AT16: 2 | AU16: =AT16*$G$16 -> 0 | AV16: 2 | AW16: =AV16*$G$16 -> 0 | AX16: 2 | AY16: =AX16*$G$16 -> 0 | AZ16: 2 | BA16: =AZ16*$G$16 -> 0 | BB16: 2 | BC16: =BB16*$G$16 -> 0 | BD16: 2 | BE16: =BD16*$G$16 -> 0 | BF16: 2 | BG16: =BF16*$G$16 -> 0 | BH16: 2 | BI16: =BH16*$G$16 -> 0 | BJ16: 2 | BK16: =BJ16*$G$16 -> 0 | BL16: 2 | BM16: =BL16*$G$16 -> 0 | BN16: 2 | BO16: =BN16*$G$16 -> 0 | BP16: 2 | BQ16: =BP16*$G$16 -> 0 | BR16: 2 | BS16: =BR16*$G$16 -> 0 | BT16: 2 | BU16: =BT16*$G$16 -> 0 | BV16: 2 | BW16: =BV16*$G$16 -> 0 | BX16: 2 | BY16: =BX16*$G$16 -> 0 | BZ16: 2 | CA16: =BZ16*$G$16 -> 0 | CB16: 2 | CC16: =CB16*$G$16 -> 0 | CD16: 2 | CE16: =CD16*$G$16 -> 0 | CF16: 2 | CG16: =CF16*$G$16 -> 0 | CH16: 2 | CI16: =CH16*$G$16 -> 0 | CJ16: 1 | CK16: =CJ16*$G$16 -> 0 | CL16: 1 | CM16: =CL16*$G$16 -> 0 | CN16: 1 | CO16: =CN16*$G$16 -> 0 | CP16: 1 | CQ16: =CP16*$G$16 -> 0 | CR16: 1 | CS16: =CR16*$G$16 -> 0 | CT16: 1 | CU16: =CT16*$G$16 -> 0 | CV16: 1 | CW16: =CV16*$G$16 -> 0 | CX16: 1 | CY16: =CX16*$G$16 -> 0 | CZ16: 1 | DA16: =CZ16*$G$16 -> 0 | DB16: 1 | DC16: =DB16*$G$16 -> 0 | DD16: 1 | DE16: =DD16*$G$16 -> 0 | DF16: 1 | DG16: =DF16*$G$16 -> 0 | DH16: 1 | DI16: =DH16*$G$16 -> 0 | DJ16: 1 | DK16: =DJ16*$G$16 -> 0 | DL16: 1 | DM16: =DL16*$G$16 -> 0 | DN16: 1 | DO16: =DN16*$G$16 -> 0 | DP16: 1 | DQ16: =DP16*$G$16 -> 0 | DR16: 1 | DS16: =DR16*$G$16 -> 0 | DT16: 1 | DU16: =DT16*$G$16 -> 0 | DV16: 1 | DW16: =DV16*$G$16 -> 0 | DX16: 1 | DY16: =DX16*$G$16 -> 0 | DZ16: 1 | EA16: =DZ16*$G$16 -> 0 | EB16: 1 | EC16: =EB16*$G$16 -> 0 | ED16: 1 | EE16: =ED16*$G$16 -> 0 | EF16: 1 | EG16: =EF16*$G$16 -> 0 | EH16: 1 | EI16: =EH16*$G$16 -> 0 | EJ16: 1 | EK16: =EJ16*$G$16 -> 0 | EL16: 1 | EM16: =EL16*$G$16 -> 0 | EN16: 1 | EO16: =EN16*$G$16 -> 0 | EP16: 1 | EQ16: =EP16*$G$16 -> 0 | ER16: 1 | ES16: =ER16*$G$16 -> 0 | ET16: 1 | EU16: =ET16*$G$16 -> 0 | EV16: 1 | EW16: =EV16*$G$16 -> 0 | EX16: 1 | EY16: =EX16*$G$16 -> 0 | EZ16: 1 | FA16: =EZ16*$G$16 -> 0 | FB16: 1 | FC16: =FB16*$G$16 -> 0 | FD16: 1 | FE16: =FD16*$G$16 -> 0 | FF16: 1 | FG16: =FF16*$G$16 -> 0 | FH16: 1 | FI16: =FH16*$G$16 -> 0 | FJ16: 1 | FK16: =FJ16*$G$16 -> 0 | FL16: 1 | FM16: =FL16*$G$16 -> 0 | FN16: 1 | FO16: =FN16*$G$16 -> 0 | FP16: 1 | FQ16: =FP16*$G$16 -> 0
A17: CAMISA LISTRAS BRANCAS | B17: 913 | C17: 9E | D17: LISTRA BRANCA | E17: 109130019E2 | F17: 2 | G17: 3 | I17: =H16*G17 -> 408 | K17: =J16*$G$17 -> 9 | M17: =L16*$G$17 -> 9 | O17: =N16*$G$17 -> 9 | Q17: =P16*$G$17 -> 9 | S17: =R16*$G$17 -> 9 | U17: =T16*$G$17 -> 9 | W17: =V16*$G$17 -> 9 | Y17: =X16*$G$17 -> 9 | AA17: =Z16*$G$17 -> 9 | AC17: =AB16*$G$17 -> 9 | AE17: =AD16*$G$17 -> 9 | AG17: =AF16*$G$17 -> 9 | AI17: =AH16*$G$17 -> 6 | AK17: =AJ16*$G$17 -> 6 | AM17: =AL16*$G$17 -> 6 | AO17: =AN16*$G$17 -> 6 | AQ17: =AP16*$G$17 -> 6 | AS17: =AR16*$G$17 -> 6 | AU17: =AT16*$G$17 -> 6 | AW17: =AV16*$G$17 -> 6 | AY17: =AX16*$G$17 -> 6 | BA17: =AZ16*$G$17 -> 6 | BC17: =BB16*$G$17 -> 6 | BE17: =BD16*$G$17 -> 6 | BG17: =BF16*$G$17 -> 6 | BI17: =BH16*$G$17 -> 6 | BK17: =BJ16*$G$17 -> 6 | BM17: =BL16*$G$17 -> 6 | BO17: =BN16*$G$17 -> 6 | BQ17: =BP16*$G$17 -> 6 | BS17: =BR16*$G$17 -> 6 | BU17: =BT16*$G$17 -> 6 | BW17: =BV16*$G$17 -> 6 | BY17: =BX16*$G$17 -> 6 | CA17: =BZ16*$G$17 -> 6 | CC17: =CB16*$G$17 -> 6 | CE17: =CD16*$G$17 -> 6 | CG17: =CF16*$G$17 -> 6 | CI17: =CH16*$G$17 -> 6 | CK17: =CJ16*$G$17 -> 3 | CM17: =CL16*$G$17 -> 3 | CO17: =CN16*$G$17 -> 3 | CQ17: =CP16*$G$17 -> 3 | CS17: =CR16*$G$17 -> 3 | CU17: =CT16*$G$17 -> 3 | CW17: =CV16*$G$17 -> 3 | CY17: =CX16*$G$17 -> 3 | DA17: =CZ16*$G$17 -> 3 | DC17: =DB16*$G$17 -> 3 | DE17: =DD16*$G$17 -> 3 | DG17: =DF16*$G$17 -> 3 | DI17: =DH16*$G$17 -> 3 | DK17: =DJ16*$G$17 -> 3 | DM17: =DL16*$G$17 -> 3 | DO17: =DN16*$G$17 -> 3 | DQ17: =DP16*$G$17 -> 3 | DS17: =DR16*$G$17 -> 3 | DU17: =DT16*$G$17 -> 3 | DW17: =DV16*$G$17 -> 3 | DY17: =DX16*$G$17 -> 3 | EA17: =DZ16*$G$17 -> 3 | EC17: =EB16*$G$17 -> 3 | EE17: =ED16*$G$17 -> 3 | EG17: =EF16*$G$17 -> 3 | EI17: =EH16*$G$17 -> 3 | EK17: =EJ16*$G$17 -> 3 | EM17: =EL16*$G$17 -> 3 | EO17: =EN16*$G$17 -> 3 | EQ17: =EP16*$G$17 -> 3 | ES17: =ER16*$G$17 -> 3 | EU17: =ET16*$G$17 -> 3 | EW17: =EV16*$G$17 -> 3 | EY17: =EX16*$G$17 -> 3 | FA17: =EZ16*$G$17 -> 3 | FC17: =FB16*$G$17 -> 3 | FE17: =FD16*$G$17 -> 3 | FG17: =FF16*$G$17 -> 3 | FI17: =FH16*$G$17 -> 3 | FK17: =FJ16*$G$17 -> 3 | FM17: =FL16*$G$17 -> 3 | FO17: =FN16*$G$17 -> 3 | FQ17: =FP16*$G$17 -> 3
A18: CAMISA LISTRAS BRANCAS | B18: 913 | C18: 9E | D18: LISTRA BRANCA | E18: 109130019E3 | F18: 3 | G18: 4 | I18: =H16*G18 -> 544 | K18: =J16*$G$18 -> 12 | M18: =L16*$G$18 -> 12 | O18: =N16*$G$18 -> 12 | Q18: =P16*$G$18 -> 12 | S18: =R16*$G$18 -> 12 | U18: =T16*$G$18 -> 12 | W18: =V16*$G$18 -> 12 | Y18: =X16*$G$18 -> 12 | AA18: =Z16*$G$18 -> 12 | AC18: =AB16*$G$18 -> 12 | AE18: =AD16*$G$18 -> 12 | AG18: =AF16*$G$18 -> 12 | AI18: =AH16*$G$18 -> 8 | AK18: =AJ16*$G$18 -> 8 | AM18: =AL16*$G$18 -> 8 | AO18: =AN16*$G$18 -> 8 | AQ18: =AP16*$G$18 -> 8 | AS18: =AR16*$G$18 -> 8 | AU18: =AT16*$G$18 -> 8 | AW18: =AV16*$G$18 -> 8 | AY18: =AX16*$G$18 -> 8 | BA18: =AZ16*$G$18 -> 8 | BC18: =BB16*$G$18 -> 8 | BE18: =BD16*$G$18 -> 8 | BG18: =BF16*$G$18 -> 8 | BI18: =BH16*$G$18 -> 8 | BK18: =BJ16*$G$18 -> 8 | BM18: =BL16*$G$18 -> 8 | BO18: =BN16*$G$18 -> 8 | BQ18: =BP16*$G$18 -> 8 | BS18: =BR16*$G$18 -> 8 | BU18: =BT16*$G$18 -> 8 | BW18: =BV16*$G$18 -> 8 | BY18: =BX16*$G$18 -> 8 | CA18: =BZ16*$G$18 -> 8 | CC18: =CB16*$G$18 -> 8 | CE18: =CD16*$G$18 -> 8 | CG18: =CF16*$G$18 -> 8 | CI18: =CH16*$G$18 -> 8 | CK18: =CJ16*$G$18 -> 4 | CM18: =CL16*$G$18 -> 4 | CO18: =CN16*$G$18 -> 4 | CQ18: =CP16*$G$18 -> 4 | CS18: =CR16*$G$18 -> 4 | CU18: =CT16*$G$18 -> 4 | CW18: =CV16*$G$18 -> 4 | CY18: =CX16*$G$18 -> 4 | DA18: =CZ16*$G$18 -> 4 | DC18: =DB16*$G$18 -> 4 | DE18: =DD16*$G$18 -> 4 | DG18: =DF16*$G$18 -> 4 | DI18: =DH16*$G$18 -> 4 | DK18: =DJ16*$G$18 -> 4 | DM18: =DL16*$G$18 -> 4 | DO18: =DN16*$G$18 -> 4 | DQ18: =DP16*$G$18 -> 4 | DS18: =DR16*$G$18 -> 4 | DU18: =DT16*$G$18 -> 4 | DW18: =DV16*$G$18 -> 4 | DY18: =DX16*$G$18 -> 4 | EA18: =DZ16*$G$18 -> 4 | EC18: =EB16*$G$18 -> 4 | EE18: =ED16*$G$18 -> 4 | EG18: =EF16*$G$18 -> 4 | EI18: =EH16*$G$18 -> 4 | EK18: =EJ16*$G$18 -> 4 | EM18: =EL16*$G$18 -> 4 | EO18: =EN16*$G$18 -> 4 | EQ18: =EP16*$G$18 -> 4 | ES18: =ER16*$G$18 -> 4 | EU18: =ET16*$G$18 -> 4 | EW18: =EV16*$G$18 -> 4 | EY18: =EX16*$G$18 -> 4 | FA18: =EZ16*$G$18 -> 4 | FC18: =FB16*$G$18 -> 4 | FE18: =FD16*$G$18 -> 4 | FG18: =FF16*$G$18 -> 4 | FI18: =FH16*$G$18 -> 4 | FK18: =FJ16*$G$18 -> 4 | FM18: =FL16*$G$18 -> 4 | FO18: =FN16*$G$18 -> 4 | FQ18: =FP16*$G$18 -> 4
A19: CAMISA LISTRAS BRANCAS | B19: 913 | C19: 9E | D19: LISTRA BRANCA | E19: 109130019E4 | F19: 4 | G19: 2 | I19: =H16*G19 -> 272 | K19: =J16*$G$19 -> 6 | M19: =L16*$G$19 -> 6 | O19: =N16*$G$19 -> 6 | Q19: =P16*$G$19 -> 6 | S19: =R16*$G$19 -> 6 | U19: =T16*$G$19 -> 6 | W19: =V16*$G$19 -> 6 | Y19: =X16*$G$19 -> 6 | AA19: =Z16*$G$19 -> 6 | AC19: =AB16*$G$19 -> 6 | AE19: =AD16*$G$19 -> 6 | AG19: =AF16*$G$19 -> 6 | AI19: =AH16*$G$19 -> 4 | AK19: =AJ16*$G$19 -> 4 | AM19: =AL16*$G$19 -> 4 | AO19: =AN16*$G$19 -> 4 | AQ19: =AP16*$G$19 -> 4 | AS19: =AR16*$G$19 -> 4 | AU19: =AT16*$G$19 -> 4 | AW19: =AV16*$G$19 -> 4 | AY19: =AX16*$G$19 -> 4 | BA19: =AZ16*$G$19 -> 4 | BC19: =BB16*$G$19 -> 4 | BE19: =BD16*$G$19 -> 4 | BG19: =BF16*$G$19 -> 4 | BI19: =BH16*$G$19 -> 4 | BK19: =BJ16*$G$19 -> 4 | BM19: =BL16*$G$19 -> 4 | BO19: =BN16*$G$19 -> 4 | BQ19: =BP16*$G$19 -> 4 | BS19: =BR16*$G$19 -> 4 | BU19: =BT16*$G$19 -> 4 | BW19: =BV16*$G$19 -> 4 | BY19: =BX16*$G$19 -> 4 | CA19: =BZ16*$G$19 -> 4 | CC19: =CB16*$G$19 -> 4 | CE19: =CD16*$G$19 -> 4 | CG19: =CF16*$G$19 -> 4 | CI19: =CH16*$G$19 -> 4 | CK19: =CJ16*$G$19 -> 2 | CM19: =CL16*$G$19 -> 2 | CO19: =CN16*$G$19 -> 2 | CQ19: =CP16*$G$19 -> 2 | CS19: =CR16*$G$19 -> 2 | CU19: =CT16*$G$19 -> 2 | CW19: =CV16*$G$19 -> 2 | CY19: =CX16*$G$19 -> 2 | DA19: =CZ16*$G$19 -> 2 | DC19: =DB16*$G$19 -> 2 | DE19: =DD16*$G$19 -> 2 | DG19: =DF16*$G$19 -> 2 | DI19: =DH16*$G$19 -> 2 | DK19: =DJ16*$G$19 -> 2 | DM19: =DL16*$G$19 -> 2 | DO19: =DN16*$G$19 -> 2 | DQ19: =DP16*$G$19 -> 2 | DS19: =DR16*$G$19 -> 2 | DU19: =DT16*$G$19 -> 2 | DW19: =DV16*$G$19 -> 2 | DY19: =DX16*$G$19 -> 2 | EA19: =DZ16*$G$19 -> 2 | EC19: =EB16*$G$19 -> 2 | EE19: =ED16*$G$19 -> 2 | EG19: =EF16*$G$19 -> 2 | EI19: =EH16*$G$19 -> 2 | EK19: =EJ16*$G$19 -> 2 | EM19: =EL16*$G$19 -> 2 | EO19: =EN16*$G$19 -> 2 | EQ19: =EP16*$G$19 -> 2 | ES19: =ER16*$G$19 -> 2 | EU19: =ET16*$G$19 -> 2 | EW19: =EV16*$G$19 -> 2 | EY19: =EX16*$G$19 -> 2 | FA19: =EZ16*$G$19 -> 2 | FC19: =FB16*$G$19 -> 2 | FE19: =FD16*$G$19 -> 2 | FG19: =FF16*$G$19 -> 2 | FI19: =FH16*$G$19 -> 2 | FK19: =FJ16*$G$19 -> 2 | FM19: =FL16*$G$19 -> 2 | FO19: =FN16*$G$19 -> 2 | FQ19: =FP16*$G$19 -> 2
A20: CAMISA LISTRAS BRANCAS | B20: 913 | C20: 9E | D20: LISTRA BRANCA | E20: 109130019E5 | F20: 5 | G20: 1 | I20: =H16*G20 -> 136 | K20: =J16*$G$20 -> 3 | M20: =L16*$G$20 -> 3 | O20: =N16*$G$20 -> 3 | Q20: =P16*$G$20 -> 3 | S20: =R16*$G$20 -> 3 | U20: =T16*$G$20 -> 3 | W20: =V16*$G$20 -> 3 | Y20: =X16*$G$20 -> 3 | AA20: =Z16*$G$20 -> 3 | AC20: =AB16*$G$20 -> 3 | AE20: =AD16*$G$20 -> 3 | AG20: =AF16*$G$20 -> 3 | AI20: =AH16*$G$20 -> 2 | AK20: =AJ16*$G$20 -> 2 | AM20: =AL16*$G$20 -> 2 | AO20: =AN16*$G$20 -> 2 | AQ20: =AP16*$G$20 -> 2 | AS20: =AR16*$G$20 -> 2 | AU20: =AT16*$G$20 -> 2 | AW20: =AV16*$G$20 -> 2 | AY20: =AX16*$G$20 -> 2 | BA20: =AZ16*$G$20 -> 2 | BC20: =BB16*$G$20 -> 2 | BE20: =BD16*$G$20 -> 2 | BG20: =BF16*$G$20 -> 2 | BI20: =BH16*$G$20 -> 2 | BK20: =BJ16*$G$20 -> 2 | BM20: =BL16*$G$20 -> 2 | BO20: =BN16*$G$20 -> 2 | BQ20: =BP16*$G$20 -> 2 | BS20: =BR16*$G$20 -> 2 | BU20: =BT16*$G$20 -> 2 | BW20: =BV16*$G$20 -> 2 | BY20: =BX16*$G$20 -> 2 | CA20: =BZ16*$G$20 -> 2 | CC20: =CB16*$G$20 -> 2 | CE20: =CD16*$G$20 -> 2 | CG20: =CF16*$G$20 -> 2 | CI20: =CH16*$G$20 -> 2 | CK20: =CJ16*$G$20 -> 1 | CM20: =CL16*$G$20 -> 1 | CO20: =CN16*$G$20 -> 1 | CQ20: =CP16*$G$20 -> 1 | CS20: =CR16*$G$20 -> 1 | CU20: =CT16*$G$20 -> 1 | CW20: =CV16*$G$20 -> 1 | CY20: =CX16*$G$20 -> 1 | DA20: =CZ16*$G$20 -> 1 | DC20: =DB16*$G$20 -> 1 | DE20: =DD16*$G$20 -> 1 | DG20: =DF16*$G$20 -> 1 | DI20: =DH16*$G$20 -> 1 | DK20: =DJ16*$G$20 -> 1 | DM20: =DL16*$G$20 -> 1 | DO20: =DN16*$G$20 -> 1 | DQ20: =DP16*$G$20 -> 1 | DS20: =DR16*$G$20 -> 1 | DU20: =DT16*$G$20 -> 1 | DW20: =DV16*$G$20 -> 1 | DY20: =DX16*$G$20 -> 1 | EA20: =DZ16*$G$20 -> 1 | EC20: =EB16*$G$20 -> 1 | EE20: =ED16*$G$20 -> 1 | EG20: =EF16*$G$20 -> 1 | EI20: =EH16*$G$20 -> 1 | EK20: =EJ16*$G$20 -> 1 | EM20: =EL16*$G$20 -> 1 | EO20: =EN16*$G$20 -> 1 | EQ20: =EP16*$G$20 -> 1 | ES20: =ER16*$G$20 -> 1 | EU20: =ET16*$G$20 -> 1 | EW20: =EV16*$G$20 -> 1 | EY20: =EX16*$G$20 -> 1 | FA20: =EZ16*$G$20 -> 1 | FC20: =FB16*$G$20 -> 1 | FE20: =FD16*$G$20 -> 1 | FG20: =FF16*$G$20 -> 1 | FI20: =FH16*$G$20 -> 1 | FK20: =FJ16*$G$20 -> 1 | FM20: =FL16*$G$20 -> 1 | FO20: =FN16*$G$20 -> 1 | FQ20: =FP16*$G$20 -> 1
A21: CAMISA LISTRAS BRANCAS | B21: 913 | C21: 9E | D21: LISTRA BRANCA | E21: 109130019E6 | F21: 6 | G21: 0 | I21: =H16*G21 -> 0 | K21: =J16*$G$21 -> 0 | M21: =L16*$G$21 -> 0 | O21: =N16*$G$21 -> 0 | Q21: =P16*$G$21 -> 0 | S21: =R16*$G$21 -> 0 | U21: =T16*$G$21 -> 0 | W21: =V16*$G$21 -> 0 | Y21: =X16*$G$21 -> 0 | AA21: =Z16*$G$21 -> 0 | AC21: =AB16*$G$21 -> 0 | AE21: =AD16*$G$21 -> 0 | AG21: =AF16*$G$21 -> 0 | AI21: =AH16*$G$21 -> 0 | AK21: =AJ16*$G$21 -> 0 | AM21: =AL16*$G$21 -> 0 | AO21: =AN16*$G$21 -> 0 | AQ21: =AP16*$G$21 -> 0 | AS21: =AR16*$G$21 -> 0 | AU21: =AT16*$G$21 -> 0 | AW21: =AV16*$G$21 -> 0 | AY21: =AX16*$G$21 -> 0 | BA21: =AZ16*$G$21 -> 0 | BC21: =BB16*$G$21 -> 0 | BE21: =BD16*$G$21 -> 0 | BG21: =BF16*$G$21 -> 0 | BI21: =BH16*$G$21 -> 0 | BK21: =BJ16*$G$21 -> 0 | BM21: =BL16*$G$21 -> 0 | BO21: =BN16*$G$21 -> 0 | BQ21: =BP16*$G$21 -> 0 | BS21: =BR16*$G$21 -> 0 | BU21: =BT16*$G$21 -> 0 | BW21: =BV16*$G$21 -> 0 | BY21: =BX16*$G$21 -> 0 | CA21: =BZ16*$G$21 -> 0 | CC21: =CB16*$G$21 -> 0 | CE21: =CD16*$G$21 -> 0 | CG21: =CF16*$G$21 -> 0 | CI21: =CH16*$G$21 -> 0 | CK21: =CJ16*$G$21 -> 0 | CM21: =CL16*$G$21 -> 0 | CO21: =CN16*$G$21 -> 0 | CQ21: =CP16*$G$21 -> 0 | CS21: =CR16*$G$21 -> 0 | CU21: =CT16*$G$21 -> 0 | CW21: =CV16*$G$21 -> 0 | CY21: =CX16*$G$21 -> 0 | DA21: =CZ16*$G$21 -> 0 | DC21: =DB16*$G$21 -> 0 | DE21: =DD16*$G$21 -> 0 | DG21: =DF16*$G$21 -> 0 | DI21: =DH16*$G$21 -> 0 | DK21: =DJ16*$G$21 -> 0 | DM21: =DL16*$G$21 -> 0 | DO21: =DN16*$G$21 -> 0 | DQ21: =DP16*$G$21 -> 0 | DS21: =DR16*$G$21 -> 0 | DU21: =DT16*$G$21 -> 0 | DW21: =DV16*$G$21 -> 0 | DY21: =DX16*$G$21 -> 0 | EA21: =DZ16*$G$21 -> 0 | EC21: =EB16*$G$21 -> 0 | EE21: =ED16*$G$21 -> 0 | EG21: =EF16*$G$21 -> 0 | EI21: =EH16*$G$21 -> 0 | EK21: =EJ16*$G$21 -> 0 | EM21: =EL16*$G$21 -> 0 | EO21: =EN16*$G$21 -> 0 | EQ21: =EP16*$G$21 -> 0 | ES21: =ER16*$G$21 -> 0 | EU21: =ET16*$G$21 -> 0 | EW21: =EV16*$G$21 -> 0 | EY21: =EX16*$G$21 -> 0 | FA21: =EZ16*$G$21 -> 0 | FC21: =FB16*$G$21 -> 0 | FE21: =FD16*$G$21 -> 0 | FG21: =FF16*$G$21 -> 0 | FI21: =FH16*$G$21 -> 0 | FK21: =FJ16*$G$21 -> 0 | FM21: =FL16*$G$21 -> 0 | FO21: =FN16*$G$21 -> 0 | FQ21: =FP16*$G$21 -> 0
A22: CAMISA LISTRAS BRANCAS | B22: 913 | C22: 9C | D22: LISTRA BRANCA | E22: 109130019C1 | F22: 1 | G22: 0 | H22: 1305 | I22: =H22*G22 -> 0 | J22: 10 | K22: =J22*$G$22 -> 0 | L22: 10 | M22: =L22*$G$22 -> 0 | N22: 10 | O22: =N22*$G$22 -> 0 | P22: 10 | Q22: =P22*$G$22 -> 0 | R22: 10 | S22: =R22*$G$22 -> 0 | T22: 10 | U22: =T22*$G$22 -> 0 | V22: 10 | W22: =V22*$G$22 -> 0 | X22: 10 | Y22: =X22*$G$22 -> 0 | Z22: 10 | AA22: =Z22*$G$22 -> 0 | AB22: 10 | AC22: =AB22*$G$22 -> 0 | AD22: 10 | AE22: =AD22*$G$22 -> 0 | AF22: 10 | AG22: =AF22*$G$22 -> 0 | AH22: 10 | AI22: =AH22*$G$22 -> 0 | AJ22: 8 | AK22: =AJ22*$G$22 -> 0 | AL22: 8 | AM22: =AL22*$G$22 -> 0 | AN22: 8 | AO22: =AN22*$G$22 -> 0 | AP22: 8 | AQ22: =AP22*$G$22 -> 0 | AR22: 8 | AS22: =AR22*$G$22 -> 0 | AT22: 8 | AU22: =AT22*$G$22 -> 0 | AV22: 8 | AW22: =AV22*$G$22 -> 0 | AX22: 8 | AY22: =AX22*$G$22 -> 0 | AZ22: 8 | BA22: =AZ22*$G$22 -> 0 | BB22: 8 | BC22: =BB22*$G$22 -> 0 | BD22: 8 | BE22: =BD22*$G$22 -> 0 | BF22: 8 | BG22: =BF22*$G$22 -> 0 | BH22: 8 | BI22: =BH22*$G$22 -> 0 | BJ22: 8 | BK22: =BJ22*$G$22 -> 0 | BL22: 8 | BM22: =BL22*$G$22 -> 0 | BN22: 8 | BO22: =BN22*$G$22 -> 0 | BP22: 8 | BQ22: =BP22*$G$22 -> 0 | BR22: 8 | BS22: =BR22*$G$22 -> 0 | BT22: 8 | BU22: =BT22*$G$22 -> 0 | BV22: 8 | BW22: =BV22*$G$22 -> 0 | BX22: 8 | BY22: =BX22*$G$22 -> 0 | BZ22: 8 | CA22: =BZ22*$G$22 -> 0 | CB22: 8 | CC22: =CB22*$G$22 -> 0 | CD22: 8 | CE22: =CD22*$G$22 -> 0 | CF22: 8 | CG22: =CF22*$G$22 -> 0 | CH22: 8 | CI22: =CH22*$G$22 -> 0 | CJ22: 8 | CK22: =CJ22*$G$22 -> 0 | CL22: 8 | CM22: =CL22*$G$22 -> 0 | CN22: 8 | CO22: =CN22*$G$22 -> 0 | CP22: 8 | CQ22: =CP22*$G$22 -> 0 | CR22: 8 | CS22: =CR22*$G$22 -> 0 | CT22: 8 | CU22: =CT22*$G$22 -> 0 | CV22: 8 | CW22: =CV22*$G$22 -> 0 | CX22: 8 | CY22: =CX22*$G$22 -> 0 | CZ22: 8 | DA22: =CZ22*$G$22 -> 0 | DB22: 8 | DC22: =DB22*$G$22 -> 0 | DD22: 8 | DE22: =DD22*$G$22 -> 0 | DF22: 8 | DG22: =DF22*$G$22 -> 0 | DH22: 8 | DI22: =DH22*$G$22 -> 0 | DJ22: 8 | DK22: =DJ22*$G$22 -> 0 | DL22: 8 | DM22: =DL22*$G$22 -> 0 | DN22: 8 | DO22: =DN22*$G$22 -> 0 | DP22: 8 | DQ22: =DP22*$G$22 -> 0 | DR22: 8 | DS22: =DR22*$G$22 -> 0 | DT22: 8 | DU22: =DT22*$G$22 -> 0 | DV22: 8 | DW22: =DV22*$G$22 -> 0 | DX22: 8 | DY22: =DX22*$G$22 -> 0 | DZ22: 8 | EA22: =DZ22*$G$22 -> 0 | EB22: 8 | EC22: =EB22*$G$22 -> 0 | ED22: 8 | EE22: =ED22*$G$22 -> 0 | EF22: 8 | EG22: =EF22*$G$22 -> 0 | EH22: 8 | EI22: =EH22*$G$22 -> 0 | EJ22: 8 | EK22: =EJ22*$G$22 -> 0 | EL22: 8 | EM22: =EL22*$G$22 -> 0 | EN22: 8 | EO22: =EN22*$G$22 -> 0 | EP22: 8 | EQ22: =EP22*$G$22 -> 0 | ER22: 8 | ES22: =ER22*$G$22 -> 0 | ET22: 8 | EU22: =ET22*$G$22 -> 0 | EV22: 8 | EW22: =EV22*$G$22 -> 0 | EX22: 8 | EY22: =EX22*$G$22 -> 0 | EZ22: 8 | FA22: =EZ22*$G$22 -> 0 | FB22: 8 | FC22: =FB22*$G$22 -> 0 | FD22: 8 | FE22: =FD22*$G$22 -> 0 | FF22: 8 | FG22: =FF22*$G$22 -> 0 | FH22: 8 | FI22: =FH22*$G$22 -> 0 | FJ22: 8 | FK22: =FJ22*$G$22 -> 0 | FL22: 8 | FM22: =FL22*$G$22 -> 0 | FN22: 8 | FO22: =FN22*$G$22 -> 0 | FP22: 8 | FQ22: =FP22*$G$22 -> 0
A23: CAMISA LISTRAS BRANCAS | B23: 913 | C23: 9C | D23: LISTRA BRANCA | E23: 109130019C2 | F23: 2 | G23: 6 | I23: =H22*G23 -> 7830 | K23: =J22*$G$23 -> 60 | M23: =L22*$G$23 -> 60 | O23: =N22*$G$23 -> 60 | Q23: =P22*$G$23 -> 60 | S23: =R22*$G$23 -> 60 | U23: =T22*$G$23 -> 60 | W23: =V22*$G$23 -> 60 | Y23: =X22*$G$23 -> 60 | AA23: =Z22*$G$23 -> 60 | AC23: =AB22*$G$23 -> 60 | AE23: =AD22*$G$23 -> 60 | AG23: =AF22*$G$23 -> 60 | AI23: =AH22*$G$23 -> 60 | AK23: =AJ22*$G$23 -> 48 | AM23: =AL22*$G$23 -> 48 | AO23: =AN22*$G$23 -> 48 | AQ23: =AP22*$G$23 -> 48 | AS23: =AR22*$G$23 -> 48 | AU23: =AT22*$G$23 -> 48 | AW23: =AV22*$G$23 -> 48 | AY23: =AX22*$G$23 -> 48 | BA23: =AZ22*$G$23 -> 48 | BC23: =BB22*$G$23 -> 48 | BE23: =BD22*$G$23 -> 48 | BG23: =BF22*$G$23 -> 48 | BI23: =BH22*$G$23 -> 48 | BK23: =BJ22*$G$23 -> 48 | BM23: =BL22*$G$23 -> 48 | BO23: =BN22*$G$23 -> 48 | BQ23: =BP22*$G$23 -> 48 | BS23: =BR22*$G$23 -> 48 | BU23: =BT22*$G$23 -> 48 | BW23: =BV22*$G$23 -> 48 | BY23: =BX22*$G$23 -> 48 | CA23: =BZ22*$G$23 -> 48 | CC23: =CB22*$G$23 -> 48 | CE23: =CD22*$G$23 -> 48 | CG23: =CF22*$G$23 -> 48 | CI23: =CH22*$G$23 -> 48 | CK23: =CJ22*$G$23 -> 48 | CM23: =CL22*$G$23 -> 48 | CO23: =CN22*$G$23 -> 48 | CQ23: =CP22*$G$23 -> 48 | CS23: =CR22*$G$23 -> 48 | CU23: =CT22*$G$23 -> 48 | CW23: =CV22*$G$23 -> 48 | CY23: =CX22*$G$23 -> 48 | DA23: =CZ22*$G$23 -> 48 | DC23: =DB22*$G$23 -> 48 | DE23: =DD22*$G$23 -> 48 | DG23: =DF22*$G$23 -> 48 | DI23: =DH22*$G$23 -> 48 | DK23: =DJ22*$G$23 -> 48 | DM23: =DL22*$G$23 -> 48 | DO23: =DN22*$G$23 -> 48 | DQ23: =DP22*$G$23 -> 48 | DS23: =DR22*$G$23 -> 48 | DU23: =DT22*$G$23 -> 48 | DW23: =DV22*$G$23 -> 48 | DY23: =DX22*$G$23 -> 48 | EA23: =DZ22*$G$23 -> 48 | EC23: =EB22*$G$23 -> 48 | EE23: =ED22*$G$23 -> 48 | EG23: =EF22*$G$23 -> 48 | EI23: =EH22*$G$23 -> 48 | EK23: =EJ22*$G$23 -> 48 | EM23: =EL22*$G$23 -> 48 | EO23: =EN22*$G$23 -> 48 | EQ23: =EP22*$G$23 -> 48 | ES23: =ER22*$G$23 -> 48 | EU23: =ET22*$G$23 -> 48 | EW23: =EV22*$G$23 -> 48 | EY23: =EX22*$G$23 -> 48 | FA23: =EZ22*$G$23 -> 48 | FC23: =FB22*$G$23 -> 48 | FE23: =FD22*$G$23 -> 48 | FG23: =FF22*$G$23 -> 48 | FI23: =FH22*$G$23 -> 48 | FK23: =FJ22*$G$23 -> 48 | FM23: =FL22*$G$23 -> 48 | FO23: =FN22*$G$23 -> 48 | FQ23: =FP22*$G$23 -> 48
A24: CAMISA LISTRAS BRANCAS | B24: 913 | C24: 9C | D24: LISTRA BRANCA | E24: 109130019C3 | F24: 3 | G24: 2 | I24: =H22*G24 -> 2610 | K24: =J22*$G$24 -> 20 | M24: =L22*$G$24 -> 20 | O24: =N22*$G$24 -> 20 | Q24: =P22*$G$24 -> 20 | S24: =R22*$G$24 -> 20 | U24: =T22*$G$24 -> 20 | W24: =V22*$G$24 -> 20 | Y24: =X22*$G$24 -> 20 | AA24: =Z22*$G$24 -> 20 | AC24: =AB22*$G$24 -> 20 | AE24: =AD22*$G$24 -> 20 | AG24: =AF22*$G$24 -> 20 | AI24: =AH22*$G$24 -> 20 | AK24: =AJ22*$G$24 -> 16 | AM24: =AL22*$G$24 -> 16 | AO24: =AN22*$G$24 -> 16 | AQ24: =AP22*$G$24 -> 16 | AS24: =AR22*$G$24 -> 16 | AU24: =AT22*$G$24 -> 16 | AW24: =AV22*$G$24 -> 16 | AY24: =AX22*$G$24 -> 16 | BA24: =AZ22*$G$24 -> 16 | BC24: =BB22*$G$24 -> 16 | BE24: =BD22*$G$24 -> 16 | BG24: =BF22*$G$24 -> 16 | BI24: =BH22*$G$24 -> 16 | BK24: =BJ22*$G$24 -> 16 | BM24: =BL22*$G$24 -> 16 | BO24: =BN22*$G$24 -> 16 | BQ24: =BP22*$G$24 -> 16 | BS24: =BR22*$G$24 -> 16 | BU24: =BT22*$G$24 -> 16 | BW24: =BV22*$G$24 -> 16 | BY24: =BX22*$G$24 -> 16 | CA24: =BZ22*$G$24 -> 16 | CC24: =CB22*$G$24 -> 16 | CE24: =CD22*$G$24 -> 16 | CG24: =CF22*$G$24 -> 16 | CI24: =CH22*$G$24 -> 16 | CK24: =CJ22*$G$24 -> 16 | CM24: =CL22*$G$24 -> 16 | CO24: =CN22*$G$24 -> 16 | CQ24: =CP22*$G$24 -> 16 | CS24: =CR22*$G$24 -> 16 | CU24: =CT22*$G$24 -> 16 | CW24: =CV22*$G$24 -> 16 | CY24: =CX22*$G$24 -> 16 | DA24: =CZ22*$G$24 -> 16 | DC24: =DB22*$G$24 -> 16 | DE24: =DD22*$G$24 -> 16 | DG24: =DF22*$G$24 -> 16 | DI24: =DH22*$G$24 -> 16 | DK24: =DJ22*$G$24 -> 16 | DM24: =DL22*$G$24 -> 16 | DO24: =DN22*$G$24 -> 16 | DQ24: =DP22*$G$24 -> 16 | DS24: =DR22*$G$24 -> 16 | DU24: =DT22*$G$24 -> 16 | DW24: =DV22*$G$24 -> 16 | DY24: =DX22*$G$24 -> 16 | EA24: =DZ22*$G$24 -> 16 | EC24: =EB22*$G$24 -> 16 | EE24: =ED22*$G$24 -> 16 | EG24: =EF22*$G$24 -> 16 | EI24: =EH22*$G$24 -> 16 | EK24: =EJ22*$G$24 -> 16 | EM24: =EL22*$G$24 -> 16 | EO24: =EN22*$G$24 -> 16 | EQ24: =EP22*$G$24 -> 16 | ES24: =ER22*$G$24 -> 16 | EU24: =ET22*$G$24 -> 16 | EW24: =EV22*$G$24 -> 16 | EY24: =EX22*$G$24 -> 16 | FA24: =EZ22*$G$24 -> 16 | FC24: =FB22*$G$24 -> 16 | FE24: =FD22*$G$24 -> 16 | FG24: =FF22*$G$24 -> 16 | FI24: =FH22*$G$24 -> 16 | FK24: =FJ22*$G$24 -> 16 | FM24: =FL22*$G$24 -> 16 | FO24: =FN22*$G$24 -> 16 | FQ24: =FP22*$G$24 -> 16
A25: CAMISA LISTRAS BRANCAS | B25: 913 | C25: 9C | D25: LISTRA BRANCA | E25: 109130019C4 | F25: 4 | G25: 2 | I25: =H22*G25 -> 2610 | K25: =J22*$G$25 -> 20 | M25: =L22*$G$25 -> 20 | O25: =N22*$G$25 -> 20 | Q25: =P22*$G$25 -> 20 | S25: =R22*$G$25 -> 20 | U25: =T22*$G$25 -> 20 | W25: =V22*$G$25 -> 20 | Y25: =X22*$G$25 -> 20 | AA25: =Z22*$G$25 -> 20 | AC25: =AB22*$G$25 -> 20 | AE25: =AD22*$G$25 -> 20 | AG25: =AF22*$G$25 -> 20 | AI25: =AH22*$G$25 -> 20 | AK25: =AJ22*$G$25 -> 16 | AM25: =AL22*$G$25 -> 16 | AO25: =AN22*$G$25 -> 16 | AQ25: =AP22*$G$25 -> 16 | AS25: =AR22*$G$25 -> 16 | AU25: =AT22*$G$25 -> 16 | AW25: =AV22*$G$25 -> 16 | AY25: =AX22*$G$25 -> 16 | BA25: =AZ22*$G$25 -> 16 | BC25: =BB22*$G$25 -> 16 | BE25: =BD22*$G$25 -> 16 | BG25: =BF22*$G$25 -> 16 | BI25: =BH22*$G$25 -> 16 | BK25: =BJ22*$G$25 -> 16 | BM25: =BL22*$G$25 -> 16 | BO25: =BN22*$G$25 -> 16 | BQ25: =BP22*$G$25 -> 16 | BS25: =BR22*$G$25 -> 16 | BU25: =BT22*$G$25 -> 16 | BW25: =BV22*$G$25 -> 16 | BY25: =BX22*$G$25 -> 16 | CA25: =BZ22*$G$25 -> 16 | CC25: =CB22*$G$25 -> 16 | CE25: =CD22*$G$25 -> 16 | CG25: =CF22*$G$25 -> 16 | CI25: =CH22*$G$25 -> 16 | CK25: =CJ22*$G$25 -> 16 | CM25: =CL22*$G$25 -> 16 | CO25: =CN22*$G$25 -> 16 | CQ25: =CP22*$G$25 -> 16 | CS25: =CR22*$G$25 -> 16 | CU25: =CT22*$G$25 -> 16 | CW25: =CV22*$G$25 -> 16 | CY25: =CX22*$G$25 -> 16 | DA25: =CZ22*$G$25 -> 16 | DC25: =DB22*$G$25 -> 16 | DE25: =DD22*$G$25 -> 16 | DG25: =DF22*$G$25 -> 16 | DI25: =DH22*$G$25 -> 16 | DK25: =DJ22*$G$25 -> 16 | DM25: =DL22*$G$25 -> 16 | DO25: =DN22*$G$25 -> 16 | DQ25: =DP22*$G$25 -> 16 | DS25: =DR22*$G$25 -> 16 | DU25: =DT22*$G$25 -> 16 | DW25: =DV22*$G$25 -> 16 | DY25: =DX22*$G$25 -> 16 | EA25: =DZ22*$G$25 -> 16 | EC25: =EB22*$G$25 -> 16 | EE25: =ED22*$G$25 -> 16 | EG25: =EF22*$G$25 -> 16 | EI25: =EH22*$G$25 -> 16 | EK25: =EJ22*$G$25 -> 16 | EM25: =EL22*$G$25 -> 16 | EO25: =EN22*$G$25 -> 16 | EQ25: =EP22*$G$25 -> 16 | ES25: =ER22*$G$25 -> 16 | EU25: =ET22*$G$25 -> 16 | EW25: =EV22*$G$25 -> 16 | EY25: =EX22*$G$25 -> 16 | FA25: =EZ22*$G$25 -> 16 | FC25: =FB22*$G$25 -> 16 | FE25: =FD22*$G$25 -> 16 | FG25: =FF22*$G$25 -> 16 | FI25: =FH22*$G$25 -> 16 | FK25: =FJ22*$G$25 -> 16 | FM25: =FL22*$G$25 -> 16 | FO25: =FN22*$G$25 -> 16 | FQ25: =FP22*$G$25 -> 16
A26: CAMISA LISTRAS BRANCAS | B26: 913 | C26: 9C | D26: LISTRA BRANCA | E26: 109130019C5 | F26: 5 | G26: 0 | I26: =H22*G26 -> 0 | K26: =J22*$G$26 -> 0 | M26: =L22*$G$26 -> 0 | O26: =N22*$G$26 -> 0 | Q26: =P22*$G$26 -> 0 | S26: =R22*$G$26 -> 0 | U26: =T22*$G$26 -> 0 | W26: =V22*$G$26 -> 0 | Y26: =X22*$G$26 -> 0 | AA26: =Z22*$G$26 -> 0 | AC26: =AB22*$G$26 -> 0 | AE26: =AD22*$G$26 -> 0 | AG26: =AF22*$G$26 -> 0 | AI26: =AH22*$G$26 -> 0 | AK26: =AJ22*$G$26 -> 0 | AM26: =AL22*$G$26 -> 0 | AO26: =AN22*$G$26 -> 0 | AQ26: =AP22*$G$26 -> 0 | AS26: =AR22*$G$26 -> 0 | AU26: =AT22*$G$26 -> 0 | AW26: =AV22*$G$26 -> 0 | AY26: =AX22*$G$26 -> 0 | BA26: =AZ22*$G$26 -> 0 | BC26: =BB22*$G$26 -> 0 | BE26: =BD22*$G$26 -> 0 | BG26: =BF22*$G$26 -> 0 | BI26: =BH22*$G$26 -> 0 | BK26: =BJ22*$G$26 -> 0 | BM26: =BL22*$G$26 -> 0 | BO26: =BN22*$G$26 -> 0 | BQ26: =BP22*$G$26 -> 0 | BS26: =BR22*$G$26 -> 0 | BU26: =BT22*$G$26 -> 0 | BW26: =BV22*$G$26 -> 0 | BY26: =BX22*$G$26 -> 0 | CA26: =BZ22*$G$26 -> 0 | CC26: =CB22*$G$26 -> 0 | CE26: =CD22*$G$26 -> 0 | CG26: =CF22*$G$26 -> 0 | CI26: =CH22*$G$26 -> 0 | CK26: =CJ22*$G$26 -> 0 | CM26: =CL22*$G$26 -> 0 | CO26: =CN22*$G$26 -> 0 | CQ26: =CP22*$G$26 -> 0 | CS26: =CR22*$G$26 -> 0 | CU26: =CT22*$G$26 -> 0 | CW26: =CV22*$G$26 -> 0 | CY26: =CX22*$G$26 -> 0 | DA26: =CZ22*$G$26 -> 0 | DC26: =DB22*$G$26 -> 0 | DE26: =DD22*$G$26 -> 0 | DG26: =DF22*$G$26 -> 0 | DI26: =DH22*$G$26 -> 0 | DK26: =DJ22*$G$26 -> 0 | DM26: =DL22*$G$26 -> 0 | DO26: =DN22*$G$26 -> 0 | DQ26: =DP22*$G$26 -> 0 | DS26: =DR22*$G$26 -> 0 | DU26: =DT22*$G$26 -> 0 | DW26: =DV22*$G$26 -> 0 | DY26: =DX22*$G$26 -> 0 | EA26: =DZ22*$G$26 -> 0 | EC26: =EB22*$G$26 -> 0 | EE26: =ED22*$G$26 -> 0 | EG26: =EF22*$G$26 -> 0 | EI26: =EH22*$G$26 -> 0 | EK26: =EJ22*$G$26 -> 0 | EM26: =EL22*$G$26 -> 0 | EO26: =EN22*$G$26 -> 0 | EQ26: =EP22*$G$26 -> 0 | ES26: =ER22*$G$26 -> 0 | EU26: =ET22*$G$26 -> 0 | EW26: =EV22*$G$26 -> 0 | EY26: =EX22*$G$26 -> 0 | FA26: =EZ22*$G$26 -> 0 | FC26: =FB22*$G$26 -> 0 | FE26: =FD22*$G$26 -> 0 | FG26: =FF22*$G$26 -> 0 | FI26: =FH22*$G$26 -> 0 | FK26: =FJ22*$G$26 -> 0 | FM26: =FL22*$G$26 -> 0 | FO26: =FN22*$G$26 -> 0 | FQ26: =FP22*$G$26 -> 0
A27: CAMISA LISTRAS BRANCAS | B27: 913 | C27: 9C | D27: LISTRA BRANCA | E27: 109130019C6 | F27: 6 | G27: 0 | I27: =H22*G27 -> 0 | K27: =J22*$G$27 -> 0 | M27: =L22*$G$27 -> 0 | O27: =N22*$G$27 -> 0 | Q27: =P22*$G$27 -> 0 | S27: =R22*$G$27 -> 0 | U27: =T22*$G$27 -> 0 | W27: =V22*$G$27 -> 0 | Y27: =X22*$G$27 -> 0 | AA27: =Z22*$G$27 -> 0 | AC27: =AB22*$G$27 -> 0 | AE27: =AD22*$G$27 -> 0 | AG27: =AF22*$G$27 -> 0 | AI27: =AH22*$G$27 -> 0 | AK27: =AJ22*$G$27 -> 0 | AM27: =AL22*$G$27 -> 0 | AO27: =AN22*$G$27 -> 0 | AQ27: =AP22*$G$27 -> 0 | AS27: =AR22*$G$27 -> 0 | AU27: =AT22*$G$27 -> 0 | AW27: =AV22*$G$27 -> 0 | AY27: =AX22*$G$27 -> 0 | BA27: =AZ22*$G$27 -> 0 | BC27: =BB22*$G$27 -> 0 | BE27: =BD22*$G$27 -> 0 | BG27: =BF22*$G$27 -> 0 | BI27: =BH22*$G$27 -> 0 | BK27: =BJ22*$G$27 -> 0 | BM27: =BL22*$G$27 -> 0 | BO27: =BN22*$G$27 -> 0 | BQ27: =BP22*$G$27 -> 0 | BS27: =BR22*$G$27 -> 0 | BU27: =BT22*$G$27 -> 0 | BW27: =BV22*$G$27 -> 0 | BY27: =BX22*$G$27 -> 0 | CA27: =BZ22*$G$27 -> 0 | CC27: =CB22*$G$27 -> 0 | CE27: =CD22*$G$27 -> 0 | CG27: =CF22*$G$27 -> 0 | CI27: =CH22*$G$27 -> 0 | CK27: =CJ22*$G$27 -> 0 | CM27: =CL22*$G$27 -> 0 | CO27: =CN22*$G$27 -> 0 | CQ27: =CP22*$G$27 -> 0 | CS27: =CR22*$G$27 -> 0 | CU27: =CT22*$G$27 -> 0 | CW27: =CV22*$G$27 -> 0 | CY27: =CX22*$G$27 -> 0 | DA27: =CZ22*$G$27 -> 0 | DC27: =DB22*$G$27 -> 0 | DE27: =DD22*$G$27 -> 0 | DG27: =DF22*$G$27 -> 0 | DI27: =DH22*$G$27 -> 0 | DK27: =DJ22*$G$27 -> 0 | DM27: =DL22*$G$27 -> 0 | DO27: =DN22*$G$27 -> 0 | DQ27: =DP22*$G$27 -> 0 | DS27: =DR22*$G$27 -> 0 | DU27: =DT22*$G$27 -> 0 | DW27: =DV22*$G$27 -> 0 | DY27: =DX22*$G$27 -> 0 | EA27: =DZ22*$G$27 -> 0 | EC27: =EB22*$G$27 -> 0 | EE27: =ED22*$G$27 -> 0 | EG27: =EF22*$G$27 -> 0 | EI27: =EH22*$G$27 -> 0 | EK27: =EJ22*$G$27 -> 0 | EM27: =EL22*$G$27 -> 0 | EO27: =EN22*$G$27 -> 0 | EQ27: =EP22*$G$27 -> 0 | ES27: =ER22*$G$27 -> 0 | EU27: =ET22*$G$27 -> 0 | EW27: =EV22*$G$27 -> 0 | EY27: =EX22*$G$27 -> 0 | FA27: =EZ22*$G$27 -> 0 | FC27: =FB22*$G$27 -> 0 | FE27: =FD22*$G$27 -> 0 | FG27: =FF22*$G$27 -> 0 | FI27: =FH22*$G$27 -> 0 | FK27: =FJ22*$G$27 -> 0 | FM27: =FL22*$G$27 -> 0 | FO27: =FN22*$G$27 -> 0 | FQ27: =FP22*$G$27 -> 0
A28: CAMISAS LISTRAS PRETAS | B28: 913 | C28: 9P | D28: LISTRA PRETA | E28: 109130019P1 | F28: 1 | G28: 0 | H28: 520 | I28: =H28*G28 -> 0 | J28: 4 | K28: =J28*$G$28 -> 0 | L28: 4 | M28: =L28*$G$28 -> 0 | N28: 4 | O28: =N28*$G$28 -> 0 | P28: 4 | Q28: =P28*$G$28 -> 0 | R28: 4 | S28: =R28*$G$28 -> 0 | T28: 4 | U28: =T28*$G$28 -> 0 | V28: 4 | W28: =V28*$G$28 -> 0 | X28: 4 | Y28: =X28*$G$28 -> 0 | Z28: 4 | AA28: =Z28*$G$28 -> 0 | AB28: 4 | AC28: =AB28*$G$28 -> 0 | AD28: 4 | AE28: =AD28*$G$28 -> 0 | AF28: 4 | AG28: =AF28*$G$28 -> 0 | AH28: 4 | AI28: =AH28*$G$28 -> 0 | AJ28: 4 | AK28: =AJ28*$G$28 -> 0 | AL28: 4 | AM28: =AL28*$G$28 -> 0 | AN28: 4 | AO28: =AN28*$G$28 -> 0 | AP28: 4 | AQ28: =AP28*$G$28 -> 0 | AR28: 4 | AS28: =AR28*$G$28 -> 0 | AT28: 4 | AU28: =AT28*$G$28 -> 0 | AV28: 3 | AW28: =AV28*$G$28 -> 0 | AX28: 3 | AY28: =AX28*$G$28 -> 0 | AZ28: 3 | BA28: =AZ28*$G$28 -> 0 | BB28: 3 | BC28: =BB28*$G$28 -> 0 | BD28: 3 | BE28: =BD28*$G$28 -> 0 | BF28: 3 | BG28: =BF28*$G$28 -> 0 | BH28: 3 | BI28: =BH28*$G$28 -> 0 | BJ28: 3 | BK28: =BJ28*$G$28 -> 0 | BL28: 3 | BM28: =BL28*$G$28 -> 0 | BN28: 3 | BO28: =BN28*$G$28 -> 0 | BP28: 3 | BQ28: =BP28*$G$28 -> 0 | BR28: 3 | BS28: =BR28*$G$28 -> 0 | BT28: 3 | BU28: =BT28*$G$28 -> 0 | BV28: 3 | BW28: =BV28*$G$28 -> 0 | BX28: 3 | BY28: =BX28*$G$28 -> 0 | BZ28: 3 | CA28: =BZ28*$G$28 -> 0 | CB28: 3 | CC28: =CB28*$G$28 -> 0 | CD28: 3 | CE28: =CD28*$G$28 -> 0 | CF28: 3 | CG28: =CF28*$G$28 -> 0 | CH28: 3 | CI28: =CH28*$G$28 -> 0 | CJ28: 3 | CK28: =CJ28*$G$28 -> 0 | CL28: 3 | CM28: =CL28*$G$28 -> 0 | CN28: 3 | CO28: =CN28*$G$28 -> 0 | CP28: 3 | CQ28: =CP28*$G$28 -> 0 | CR28: 3 | CS28: =CR28*$G$28 -> 0 | CT28: 3 | CU28: =CT28*$G$28 -> 0 | CV28: 3 | CW28: =CV28*$G$28 -> 0 | CX28: 3 | CY28: =CX28*$G$28 -> 0 | CZ28: 3 | DA28: =CZ28*$G$28 -> 0 | DB28: 3 | DC28: =DB28*$G$28 -> 0 | DD28: 3 | DE28: =DD28*$G$28 -> 0 | DF28: 3 | DG28: =DF28*$G$28 -> 0 | DH28: 3 | DI28: =DH28*$G$28 -> 0 | DJ28: 3 | DK28: =DJ28*$G$28 -> 0 | DL28: 3 | DM28: =DL28*$G$28 -> 0 | DN28: 3 | DO28: =DN28*$G$28 -> 0 | DP28: 3 | DQ28: =DP28*$G$28 -> 0 | DR28: 3 | DS28: =DR28*$G$28 -> 0 | DT28: 3 | DU28: =DT28*$G$28 -> 0 | DV28: 3 | DW28: =DV28*$G$28 -> 0 | DX28: 3 | DY28: =DX28*$G$28 -> 0 | DZ28: 3 | EA28: =DZ28*$G$28 -> 0 | EB28: 3 | EC28: =EB28*$G$28 -> 0 | ED28: 3 | EE28: =ED28*$G$28 -> 0 | EF28: 3 | EG28: =EF28*$G$28 -> 0 | EH28: 3 | EI28: =EH28*$G$28 -> 0 | EJ28: 3 | EK28: =EJ28*$G$28 -> 0 | EL28: 3 | EM28: =EL28*$G$28 -> 0 | EN28: 3 | EO28: =EN28*$G$28 -> 0 | EP28: 3 | EQ28: =EP28*$G$28 -> 0 | ER28: 3 | ES28: =ER28*$G$28 -> 0 | ET28: 3 | EU28: =ET28*$G$28 -> 0 | EV28: 3 | EW28: =EV28*$G$28 -> 0 | EX28: 3 | EY28: =EX28*$G$28 -> 0 | EZ28: 3 | FA28: =EZ28*$G$28 -> 0 | FB28: 3 | FC28: =FB28*$G$28 -> 0 | FD28: 3 | FE28: =FD28*$G$28 -> 0 | FF28: 3 | FG28: =FF28*$G$28 -> 0 | FH28: 3 | FI28: =FH28*$G$28 -> 0 | FJ28: 3 | FK28: =FJ28*$G$28 -> 0 | FL28: 3 | FM28: =FL28*$G$28 -> 0 | FN28: 3 | FO28: =FN28*$G$28 -> 0 | FP28: 2 | FQ28: =FP28*$G$28 -> 0
